Workbook

Sheet Client Books
A1: [ENTITY NAME]
A2: EIN: [XX-XXXXXXX] | Tax Year: [Start] - [End] | [Accrual/Cash] Basis | [#] Partners ([Split])
A4: Acct # | B4: Account Name | C4: Debit | D4: Credit
A5: ASSETS
A6: 1000 | B6: Cash - Operating
A7: 1010 | B7: Cash - Savings
A8: 1050 | B8: Petty Cash
A9: 1100 | B9: Accounts Receivable
A10: 1110 | B10: Allowance for Doubtful Accounts
A11: 1150 | B11: Notes Receivable - Current
A12: 1200 | B12: Inventory (MUST = PY Ending Inventory)
A13: 1250 | B13: Prepaid Insurance
A14: 1260 | B14: Prepaid Rent
A15: 1300 | B15: Investments - Stocks (Short-term)
A16: 1310 | B16: Investments - Municipal Bonds
A17: 1320 | B17: Investments - Corporate Bonds
... A35: 1800 | B35: Investment in Sub-Partnership (K-1 received)
A36: LIABILITIES
A37: 2000 | B37: Accounts Payable
A38: 2050 | B38: Accrued Expenses
A39: 2060 | B39: Accrued Payroll & Payroll Taxes
A40: 2070 | B40: Accrued Bonuses - Related Party (>2.5 mo unpaid)
A41: 2080 | B41: Sales Tax Payable
A42: 2100 | B42: Unearned Revenue / Deferred Revenue
A43: 2200 | B43: Line of Credit
A44: 2300 | B44: Note Payable - Bank (Current Portion)
A45: 2400 | B45: Mortgage Payable - Building
A46: 2410 | B46: Mortgage Payable - Nonrecourse portion
A47: 2500 | B47: Loans from Partners
A48: 2600 | B48: Other Long-term Liabilities
A49: PARTNERS' EQUITY
A50: 3000 | B50: Partner A - Capital Account (Beg Bal - MUST = PY Ending)
A51: 3010 | B51: Partner B - Capital Account (Beg Bal - MUST = PY Ending)
A52: 3100 | B52: Partner A - Draws/Distributions
A53: 3110 | B53: Partner B - Draws/Distributions
A54: 3200 | B54: Partner A - Contributions
A55: 3210 | B55: Partner B - Contributions
A56: REVENUE
A57: 4000 | B57: Gross Sales / Revenue
A58: 4010 | B58: Sales Returns & Allowances
...

Sheet Working Trial Balance
A1: [ENTITY NAME] - WORKING TRIAL BALANCE
A2: EIN: [XX-XXXXXXX] | Tax Year Ended: [MM/DD/YYYY] | [Accrual/Cash] Basis | [#] Partners
A3: LEGEND: | B3: Gold = Linked to Client Books | C3: Blue font = Manual input | D3: Green = Auto-balanced formula | F3: RED = MANUALLY ENTER FROM PY RETURN
A5: # | B5: 1065 Line | C5: Description | D5: Book Amount | E5: Adj# | F5: Adj (+) | G5: Adj (-) | H5: Tax Amount | I5: M-1 / K Category | J5: Adjustment Memo / Notes
A6: BALANCE SHEET — ASSETS
A7: 1 | B7: L Lines 1-2 | C7: Cash + Accounts Receivable (net of allowance) | D7: ='Client Books'!C6+'Client Books'!C7+'Client Books'!C8+'Client Books'!C9-'Client Books'!D10+'Client Books'!C11 | E7: AJE-11 | G7: 0 | H7: =D7+IF(F7,F7,0)-IF(G7,G7,0) | J7: [Enter adjustment notes here]
A8: 2 | B8: L Lines 3-5 | C8: Inventory + Prepaid + Other Current Assets | D8: ='Client Books'!C12+'Client Books'!C13+'Client Books'!C14+'Client Books'!C15+'Client Books'!C16+'Client Books'!C17 | E8: AJE-06 | G8: 0 | H8: =D8+IF(F8,F8,0)-IF(G8,G8,0) | J8: [Enter adjustment notes here]
A9: 3 | B9: L Lines 6-8 | C9: Loans to Partners + Investment in Sub-Partnership | D9: ='Client Books'!C18+'Client Books'!C35 | F9: 0 | G9: 0 | H9: =D9+IF(F9,F9,0)-IF(G9,G9,0) | J9: [Enter adjustment notes here]
A10: 4 | B10: L Lines 9-10 | C10: Fixed Assets (net of accumulated depreciation) | D10: ='Client Books'!C19+'Client Books'!C20-'Client Books'!D21+'Client Books'!C22-'Client Books'!D23+'Client Books'!C24-'Client Books'!D25+'Client Books'!C26-'Client Books'!D27+'Client Books'!C28-'Client Books'!D29 | E10: AJE-01,02 | H10: =D10+IF(F10,F10,0)-IF(G10,G10,0) | J10: [Enter adjustment notes here]
A11: 5 | B11: L Lines 11-14 | C11: Intangibles (net) + Other Assets | D11: ='Client Books'!C30-'Client Books'!D31+'Client Books'!C32-'Client Books'!D33+'Client Books'!C34 | E11: AJE-25 | G11: 0 | H11: =D11+IF(F11,F11,0)-IF(G11,G11,0) | J11: [Enter adjustment notes here]
C12: TOTAL ASSETS | D12: =D7+D8+D9+D10+D11 | H12: =H7+H8+H9+H10+H11
A14: BALANCE SHEET — LIABILITIES
A15: 6 | B15: L Lines 15-21 | C15: Total Liabilities | D15: ='Client Books'!D37+'Client Books'!D38+'Client Books'!D39+'Client Books'!D40+'Client Books'!D41+'Client Books'!D42+'Client Books'!D43+'Client Books'!D44+'Client Books'!D45+'Client Books'!D46+'Client Books'!D47+'Client Books'!D48 | F15: 0 | G15: 0 | H15: =D15+IF(F15,F15,0)-IF(G15,G15,0) | J15: [Enter adjustment notes here]
A17: BALANCE SHEET — PARTNERS' EQUITY / CAPITAL
A18: 7 | B18: L/M-2 Line 1 | C18: Beginning Capital (= PY Ending Capital) | D18: ='Client Books'!D50+'Client Books'!D51 | F18: 0 | G18: 0 | H18: =D18+IF(F18,F18,0)-IF(G18,G18,0) | J18: [Enter adjustment notes here]
A19: 8 | B19: L/M-2 Line 2 | C19: Capital Contributed During Year | D19: ='Client Books'!D54+'Client Books'!D55 | F19: 0 | G19: 0 | H19: =D19+IF(F19,F19,0)-IF(G19,G19,0) | J19: [Enter adjustment notes here]
A20: 9 | B20: L/M-2 | C20: Partner Draws / Distributions | D20: ='Client Books'!C52+'Client Books'!C53 | F20: 0 | G20: 0 | H20: =D20+IF(F20,F20,0)-IF(G20,G20,0) | J20: [Enter adjustment notes here]
A21: 10 | B21: L/M-2 | C21: Current Year Net Income (Per Books) | D21: =D94 | F21: 0 | G21: 0 | H21: =H94 | J21: Auto-tied to M-1 Line 1 (book net income). This makes BS proof work.
C22: ENDING CAPITAL (Beg + Contrib + NI - Draws) | D22: =D18+D19+D21-D20 | H22: =H18+H19+H21-H20 | J22: Book ending capital. Tax capital computed via M-2 below.
B23: CHECK | C23: Book BS Proof: Assets - Liabilities - Ending Capital (should be ZERO) | D23: =D12-D15-D22 | H23: =H12-H15-H22 | J23: BOOK col should = 0. TAX col: any nonzero amount = cumulative book-tax basis difference not yet reflected in beginning tax capital.
A25: PAGE 1 — INCOME
A26: 11 | B26: P1 Line 1a | C26: Gross Receipts or Sales | D26: ='Client Books'!D57 | F26: 0 | G26: 0 | H26: =D26+IF(F26,F26,0)-IF(G26,G26,0) | J26: [Enter adjustment notes here]
A27: 12 | B27: P1 Line 1b | C27: Returns and Allowances | D27: ='Client Books'!C58 | F27: 0 | G27: 0 | H27: =D27+IF(F27,F27,0)-IF(G27,G27,0) | J27: From Acct 4010 debit. Verify supported by credit memos.
A28: 13 | B28: P1 Line 1c | C28: Net Receipts (1a - 1b) | D28: =D26-D27 | H28: =H26-H27 | J28: Calculated.
A29: 14 | B29: P1 Line 2 | C29: Cost of Goods Sold (Schedule A) | D29: ='Client Books'!C76+'Client Books'!C77+'Client Books'!C78+'Client Books'!C79+'Client Books'!C80+'Client Books'!C81-'Client Books'!D82 | F29: 0 | G29: 0 | H29: =D29+IF(F29,F29,0)-IF(G29,G29,0) | J29: Book COGS. Sec 263A UNICAP adj handled via M-1 (not on this line). Verify beg inv = PY ending inv.
A30: 15 | B30: P1 Line 3 | C30: Gross Profit (1c - 2) | D30: =D28-D29 | H30: =H28-H29 | J30: Calculated.
A31: 16 | B31: P1 Line 4 | C31: Ordinary Income from Other Partnerships (K-1) | D31: ='Client Books'!D71 | F31: 0 | G31: 0 | H31: =D31+IF(F31,F31,0)-IF(G31,G31,0) | J31: [Enter adjustment notes here]
A32: 17 | B32: P1 Line 5 | C32: Net Farm Profit (Loss) | D32: 0 | F32: 0 | G32: 0 | H32: =D32+IF(F32,F32,0)-IF(G32,G32,0) | J32: N/A - hide if not applicable.
A33: 18 | B33: P1 Line 6 | C33: Net Gain (Loss) from Form 4797 (ordinary recapture) | D33: 0 | E33: AJE-03 | G33: 0 | H33: =D33+IF(F33,F33,0)-IF(G33,G33,0) | I33: M-1 Line 2 | J33: [Enter adjustment notes here]
A34: 19 | B34: P1 Line 7 | C34: Other Income (Loss) | D34: ='Client Books'!D73+'Client Books'!D74 | E34: AJE-04 | F34: 0 | H34: =D34+IF(F34,F34,0)-IF(G34,G34,0) | I34: M-1 Line 6 (Sec 108) | J34: [Enter adjustment notes here]
A35: 20 | B35: P1 Line 8 | C35: TOTAL INCOME (Lines 3-7) | D35: =D30+D31+D32+D33+D34 | H35: =H30+H31+H32+H33+H34 | J35: Sum of Lines 3-7.
A36: PAGE 1 — DEDUCTIONS
A37: 21 | B37: P1 Line 9 | C37: Salaries and Wages (not to partners) | D37: ='Client Books'!C84 | E37: AJE-07 | F37: 0 | H37: =D37+IF(F37,F37,0)-IF(G37,G37,0) | I37: M-1 4c (Sec 267) | J37: [Enter adjustment notes here]
A38: 22 | B38: P1 Line 10 | C38: Guaranteed Payments to Partners | D38: ='Client Books'!C85+'Client Books'!C86+'Client Books'!C87 | F38: 0 | G38: 0 | H38: =D38+IF(F38,F38,0)-IF(G38,G38,0) | J38: [Enter adjustment notes here]
A39: 23 | B39: P1 Line 11 | C39: Repairs and Maintenance | D39: ='Client Books'!C96 | F39: 0 | G39: 0 | H39: =D39+IF(F39,F39,0)-IF(G39,G39,0) | J39: [Enter adjustment notes here]
A40: 24 | B40: P1 Line 12 | C40: Bad Debts | D40: ='Client Books'!C124 | E40: AJE-08 | F40: 0 | H40: =D40+IF(F40,F40,0)-IF(G40,G40,0) | I40: M-1 4c (Reserve) | J40: [Enter adjustment notes here]
A41: 25 | B41: P1 Line 13 | C41: Rent | D41: ='Client Books'!C94+'Client Books'!C95 | F41: 0 | G41: 0 | H41: =D41+IF(F41,F41,0)-IF(G41,G41,0) | J41: [Enter adjustment notes here]
A42: 26 | B42: P1 Line 14 | C42: Taxes and Licenses | D42: ='Client Books'!C121+'Client Books'!C123 | F42: 0 | G42: 0 | H42: =D42+IF(F42,F42,0)-IF(G42,G42,0) | J42: [Enter adjustment notes here]
A43: 27 | B43: P1 Line 15 | C43: Interest (trade/business) | D43: ='Client Books'!C118+'Client Books'!C119 | F43: 0 | G43: 0 | H43: =D43+IF(F43,F43,0)-IF(G43,G43,0) | J43: [Enter adjustment notes here]
A44: 28 | B44: P1 Line 16a | C44: Tax Depreciation (MACRS, excl Sch A and Sec 179) | D44: ='Client Books'!C98 | E44: AJE-01 | G44: 0 | H44: =D44+IF(F44,F44,0)-IF(G44,G44,0) | I44: M-1 Lines 4a/7 | J44: [Enter adjustment notes here]
...

Sheet Sch K Workpaper
A1: SCHEDULE K — DETAILED WORKPAPER
A2: [ENTITY NAME] | EIN: [XX-XXXXXXX] | Tax Year Ended: [MM/DD/YYYY]
A4: # | B4: K Line | C4: Description | D4: Book Amount | E4: Tax Amount | F4: Adjustment | G4: IRC / Authority | H4: Source / WTB Ref
A5: INCOME (K Lines 1-11)
A6: 1 | B6: K Line 1 | C6: Ordinary Business Income (Loss) | D6: ='Working Trial Balance'!D70 | E6: ='Working Trial Balance'!H70 | F6: =E6-D6 | G6: Sec 702(a)(8) | H6: WTB Row 70 = P1 Line 22. QBI starting point (Sec 199A).
A7: 2 | B7: K Line 2 | C7: Net Rental RE Income (Form 8825) | D7: ='Working Trial Balance'!D71 | E7: ='Working Trial Balance'!H71 | F7: =E7-D7 | G7: Sec 469 / Sec 168 | H7: WTB Row 71. Income $96K - exp $63K = $33K book. Tax +$4.5K (rental MACRS > book depr). Passive activity.
A8: 3 | B8: K Line 3c | C8: Net Other Rental Income (Equipment) | D8: ='Working Trial Balance'!D72 | E8: ='Working Trial Balance'!H72 | F8: =E8-D8 | G8: Sec 469 | H8: WTB Row 72. Equipment rental $36K. Passive activity for all partners.
A9: 4 | B9: K Lines 4a-4c | C9: Guaranteed Payments (total) | D9: ='Working Trial Balance'!D73 | E9: ='Working Trial Balance'!H73 | F9: =E9-D9 | G9: Sec 707(c) | H9: WTB Row 73. Services 4a: $180K (A $90K + B $90K). Capital 4b: $12K. Total 4c: $192K.
A10: 5 | B10: K Line 5 | C10: Interest Income (portfolio) | D10: ='Working Trial Balance'!D74 | E10: ='Working Trial Balance'!H74 | F10: =E10-D10 | G10: Sec 702(a)(4) | H10: WTB Row 74. Bank $4.2K + corp bond $2.6K = $6.8K. Muni $3.8K excluded (K 18a).
A11: 6 | B11: K Lines 6a-6b | C11: Dividends (ordinary + qualified) | D11: ='Working Trial Balance'!D75 | E11: ='Working Trial Balance'!H75 | F11: =E11-D11 | G11: Sec 702(a)(5) | H11: WTB Row 75. Ordinary 6a: $5.5K + Qualified 6b: $8.2K = $13.7K total.
A12: 7 | B12: K Line 7 | C12: Royalties | D12: ='Working Trial Balance'!D76 | E12: ='Working Trial Balance'!H76 | F12: =E12-D12 | G12: Sec 702(a)(3) | H12: WTB Row 76. $12K.
A13: 8 | B13: K Line 8 | C13: Net Short-Term Capital Gain | D13: ='Working Trial Balance'!D77 | E13: ='Working Trial Balance'!H77 | F13: =E13-D13 | G13: Sec 702(a)(1) | H13: WTB Row 77. Stock sale $6.5K (held <1 yr).
A14: 9 | B14: K Line 9a | C14: Net Long-Term Capital Gain | D14: ='Working Trial Balance'!D78 | E14: ='Working Trial Balance'!H78 | F14: =E14-D14 | G14: Sec 702(a)(2) | H14: WTB Row 78. Stocks $18.5K + sub-partnership K-1 $4K = $22.5K.
A15: 10 | B15: K Line 9b | C15: Collectibles (28%) Gain | D15: ='Working Trial Balance'!D79 | E15: ='Working Trial Balance'!H79 | F15: =E15-D15 | G15: Sec 1(h)(5) | H15: WTB Row 79. Art sale $7.5K. 28% rate per Sec 1(h)(5).
A16: 11 | B16: K Line 10 | C16: Net Sec 1231 Gain (Loss) | D16: ='Working Trial Balance'!D80 | E16: ='Working Trial Balance'!H80 | F16: =E16-D16 | G16: Sec 1231 / 1245 | H16: WTB Row 80. Book $28K, less $12K Sec 1245 recapture to P1 L6 = $16K net 1231.
A17: 12 | B17: K Line 11 | C17: Other Income (Loss) | D17: ='Working Trial Balance'!D81 | E17: ='Working Trial Balance'!H81 | F17: =E17-D17 | G17: Sec 702(a)(7) | H17: WTB Row 81. None for this entity.
C18: K INCOME TOTAL (Lines 1-11) | D18: =SUM(D6:D17) | E18: =SUM(E6:E17) | F18: =E18-D18 | H18: WTB Row 82. Must = M-1 Line 9.
A19: SEPARATELY STATED DEDUCTIONS & OTHER ITEMS (K Lines 12-20)
A20: 13 | B20: K Line 12 | C20: Sec 179 Deduction | D20: ='Working Trial Balance'!D84 | E20: ='Working Trial Balance'!H84 | F20: =E20-D20 | G20: Sec 179 | H20: WTB Row 84. $35K on capitalized improvement. Each partner applies own limit.
A21: 14 | B21: K Line 13a | C21: Charitable Contributions | D21: ='Working Trial Balance'!D85 | E21: ='Working Trial Balance'!H85 | F21: =E21-D21 | G21: Sec 170 / 702(a)(4) | H21: WTB Row 85. $25K. Separately stated; partner applies AGI limits.
A22: 15 | B22: K Line 13b | C22: Investment Interest Expense | D22: ='Working Trial Balance'!D86 | E22: ='Working Trial Balance'!H86 | F22: =E22-D22 | G22: Sec 163(d) | H22: WTB Row 86. Margin acct interest $3.5K. Partner applies Sec 163(d) limit.
A23: 16 | B23: K Line 14a | C23: Net Earnings from Self-Employment | E23: ='Working Trial Balance'!H87 | G23: Sec 1402 | H23: WTB Row 87. = OBI + GP for services. General partners only. Not a separately stated item per se.
A24: 17 | B24: K Line 18a | C24: Tax-Exempt Interest Income | D24: ='Working Trial Balance'!D88 | E24: ='Working Trial Balance'!H88 | F24: =E24-D24 | G24: Sec 103 | H24: WTB Row 88. Muni bond $3.8K. Increases outside basis, not taxable. Flows to M-2 Line 4.
A25: 18 | B25: K Line 18c | C25: Nondeductible Expenses (total) | D25: ='Working Trial Balance'!D89 | E25: ='Working Trial Balance'!H89 | F25: =E25-D25 | G25: Various | H25: WTB Row 89. $58.6K total: meals 50% $16K, entertainment $8.5K, clubs $6K, penalties $4.5K, political $2K, life ins $9.6K, state tax $12K. Decreases basis. Flows to M-2 Line 7.
A26: 19 | B26: K Line 19a | C26: Distributions - Cash | D26: ='Working Trial Balance'!D90 | E26: ='Working Trial Balance'!H90 | F26: =E26-D26 | G26: Sec 731 | H26: WTB Row 90. A $110K + B $110K = $220K. Nontaxable to extent of basis. Flows to M-2 Line 6.
A27: 20 | B27: K Line 20 | C27: Other Information (Sec 199A QBI) | E27: ='Working Trial Balance'!H91 | G27: Sec 199A | H27: WTB Row 91. Report QBI, W-2 wages, UBIA of qualified property per partner.
A29: K-1 ALLOCATION (50/50 — 2 General Partners)
B30: K-1 Line | C30: Description | D30: K Total | E30: Partner A (50%) | F30: Partner B (50%) | H30: Source
B31: K-1 Line 1 | C31: Ordinary Business Income | D31: ='Working Trial Balance'!H70 | E31: =D31*0.5 | F31: =D31*0.5 | H31: WTB R70
B32: K-1 Line 2 | C32: Net Rental RE Income | D32: ='Working Trial Balance'!H71 | E32: =D32*0.5 | F32: =D32*0.5 | H32: WTB R71
B33: K-1 Line 3 | C33: Other Rental Income | D33: ='Working Trial Balance'!H72 | E33: =D33*0.5 | F33: =D33*0.5 | H33: WTB R72
B34: K-1 Line 4a | C34: GP for Services | D34: ='Working Trial Balance'!H73 | E34: =D34*0.5 | F34: =D34*0.5 | H34: WTB R73
B35: K-1 Line 5 | C35: Interest Income | D35: ='Working Trial Balance'!H74 | E35: =D35*0.5 | F35: =D35*0.5 | H35: WTB R74
B36: K-1 Line 6a | C36: Ordinary Dividends | D36: ='Working Trial Balance'!H75 | E36: =D36*0.5 | F36: =D36*0.5 | H36: WTB R75
B37: K-1 Line 7 | C37: Royalties | D37: ='Working Trial Balance'!H76 | E37: =D37*0.5 | F37: =D37*0.5 | H37: WTB R76
B38: K-1 Line 8 | C38: STCG | D38: ='Working Trial Balance'!H77 | E38: =D38*0.5 | F38: =D38*0.5 | H38: WTB R77
B39: K-1 Line 9a | C39: LTCG | D39: ='Working Trial Balance'!H78 | E39: =D39*0.5 | F39: =D39*0.5 | H39: WTB R78
B40: K-1 Line 10 | C40: Sec 1231 Gain | D40: ='Working Trial Balance'!H80 | E40: =D40*0.5 | F40: =D40*0.5 | H40: WTB R80
B41: K-1 Line 12 | C41: Sec 179 | D41: ='Working Trial Balance'!H84 | E41: =D41*0.5 | F41: =D41*0.5 | H41: WTB R84
B42: K-1 Line 13a | C42: Charitable | D42: ='Working Trial Balance'!H85 | E42: =D42*0.5 | F42: =D42*0.5 | H42: WTB R85
...

Sheet M-1 Workpaper
A1: SCHEDULE M-1 — BOOK-TO-TAX RECONCILIATION WORKPAPER
A2: [ENTITY NAME] | EIN: [XX-XXXXXXX] | Tax Year Ended: [MM/DD/YYYY]
A4: # | B4: M-1 Line | C4: Description | D4: Book Amount | E4: Tax Amount | F4: Difference | G4: Perm / Temp | H4: IRC / Authority | I4: Detail / WTB Ref
A5: M-1 RECONCILIATION — FORM LINES
A6: 1 | B6: M-1 Line 1 | C6: Net Income (Loss) Per Books | D6: ='Working Trial Balance'!D94 | E6: ='Working Trial Balance'!H94 | F6: =E6-D6 | I6: WTB Row 94. Computed from all Client Books revenue less all expenses. Starting point for reconciliation.
A7: 2 | B7: M-1 Line 2 | C7: Income on K not on books | D7: ='Working Trial Balance'!D95 | E7: ='Working Trial Balance'!H95 | F7: =E7-D7 | H7: Sec 1245 | I7: WTB Row 95. Sec 1245 recapture $12K: tax depreciation exceeded book on disposed equipment, creating ordinary gain on return but not on books.
A8: 3 | B8: M-1 Line 3 | C8: Guaranteed Payments | D8: ='Working Trial Balance'!D96 | E8: ='Working Trial Balance'!H96 | F8: =E8-D8 | H8: Sec 707(c) | I8: WTB Row 96. $192K. Already deducted on books as expense. Added back here per M-1 format (deducted on books, also flows to K 4c).
A9: 4 | B9: M-1 Line 4 | C9: Expenses on books NOT deducted (auto-balanced) | D9: ='Working Trial Balance'!D99 | E9: ='Working Trial Balance'!H99 | F9: =E9-D9 | H9: Various | I9: WTB Row 99. AUTO-BALANCED formula. See detail breakdown below.
A10: 5 | B10: M-1 Line 5 | C10: Total (Lines 1 + 2 + 3 + 4) | D10: ='Working Trial Balance'!D100 | E10: ='Working Trial Balance'!H100 | F10: =E10-D10 | I10: WTB Row 100.
A11: 6 | B11: M-1 Line 6 | C11: Income on books NOT on K | D11: ='Working Trial Balance'!D97 | E11: ='Working Trial Balance'!H97 | F11: =E11-D11 | H11: Sec 103 / 108 | I11: WTB Row 97. Tax-exempt muni interest $3.8K (Sec 103) + COD income excluded $15K (Sec 108 insolvency) = $18.8K.
A12: 7 | B12: M-1 Line 7 | C12: Deductions on return NOT on books | D12: ='Working Trial Balance'!D98 | E12: ='Working Trial Balance'!H98 | F12: =E12-D12 | H12: Sec 168/179 | I12: WTB Row 98. MACRS > book depr $67K + Sec 179 $35K + rental MACRS > book $4.5K = $106.5K.
A13: 8 | B13: M-1 Line 8 | C13: Total (Lines 6 + 7) | D13: ='Working Trial Balance'!D101 | E13: ='Working Trial Balance'!H101 | F13: =E13-D13 | I13: WTB Row 101.
A14: 9 | B14: M-1 Line 9 | C14: INCOME PER RETURN (Line 5 - Line 8) | D14: ='Working Trial Balance'!D102 | E14: ='Working Trial Balance'!H102 | F14: =E14-D14 | I14: WTB Row 102. Must = K Lines 1-11 total.
B15: CHECK | C15: M-1 Line 9 vs K Total | E15: ='Working Trial Balance'!H103 | I15: WTB Row 103. ZERO = balanced.
A17: M-1 LINE 4 — DETAILED BREAKDOWN OF EXPENSES ON BOOKS NOT DEDUCTED ON RETURN
B18: Adj # | C18: Description | D18: Book Expense | E18: Tax Deduction | F18: Disallowed | G18: Perm / Temp | H18: IRC / Authority | I18: WTB Ref / Explanation
B19: 4a | C19: Sec 263A UNICAP Adjustment | D19: 0 | F19: -8500 | G19: Temp | H19: Sec 263A | I19: WTB R8. Inventory capitalization. Additional $8.5K added to inventory/COGS basis. Reverses when inventory sold.
B20: 4b | C20: Sec 267 Related-Party Accrued Bonus | E20: 0 | F20: 35000 | G20: Temp | H20: Sec 267(a)(2) | I20: WTB R37 Adj(-). $35K accrued bonus to related party unpaid >2.5 months after YE. Deductible when paid.
B21: 4c | C21: Bad Debt Reserve (not specific charge-off) | E21: 0 | F21: 22000 | G21: Temp | H21: Sec 166 | I21: WTB R40 Adj(-). Book reserve method $22K. Tax requires specific charge-off; actual write-offs = $0.
B22: 4d | C22: Meals — 50% Disallowance | F22: 16000 | G22: Perm | H22: Sec 274(n) | I22: WTB R51. Book $32K, tax 50% = $16K. Nondeductible $16K to K 18c.
B23: 4e | C23: Entertainment — 100% Disallowed | E23: 0 | F23: 8500 | G23: Perm | H23: Sec 274(a)(1) | I23: WTB R52. $8.5K 100% nondeductible post-TCJA. To K 18c.
B24: 4f | C24: Club Dues — 100% Disallowed | E24: 0 | F24: 6000 | G24: Perm | H24: Sec 274(a)(3) | I24: WTB R53. Country club $6K. To K 18c.
B25: 4g | C25: Penalties & Fines | E25: 0 | F25: 4500 | G25: Perm | H25: Sec 162(f) | I25: WTB R54. $4.5K nondeductible. To K 18c.
B26: 4h | C26: Political Contributions | E26: 0 | F26: 2000 | G26: Perm | H26: Sec 162(e) | I26: WTB R55. $2K nondeductible. To K 18c.
B27: 4i | C27: Life Insurance (partnership beneficiary) | E27: 0 | F27: 9600 | G27: Perm | H27: Sec 264(a)(1) | I27: WTB R56. Key person $9.6K. Partnership is beneficiary. To K 18c.
B28: 4j | C28: State Income / Franchise Tax | E28: 0 | F28: 12000 | G28: Perm | H28: Sec 275(a)(4) | I28: WTB R57. $12K not deductible on federal partnership return. To K 18c.
B29: 4k | C29: Warranty Reserve (economic performance) | E29: 0 | F29: 15000 | G29: Temp | H29: Sec 461(h) | I29: WTB R58. $15K accrued. Not deductible until economic performance (payment/fix). Temporary diff.
B30: 4l | C30: Litigation Reserve (economic performance) | E30: 0 | F30: 40000 | G30: Temp | H30: Sec 461(h) | I30: WTB R59. $40K accrued. Not deductible until settlement/judgment. Temporary diff.
B31: 4m | C31: Partner Health Insurance (to K-1) | E31: 0 | F31: 28000 | G31: Perm* | H31: Sec 162(l) | I31: WTB R60. A $14K + B $14K. Not P1 deduction; flows to K-1 Line 13 Code M. *Deductible at partner level.
B32: 4n | C32: Capital Improvement (reclassed to Sec 179) | E32: 0 | F32: 35000 | G32: N/A | H32: Sec 179 / 263 | I32: WTB R61. Book expensed $35K. Tax: capitalize and elect Sec 179 on K Line 12. Net neutral on M-1.
B33: 4o | C33: Goodwill Amort Difference (10yr vs 15yr) | F33: 10000 | G33: Temp | H33: Sec 197 | I33: WTB R62. Book 10yr = $30K. Tax Sec 197 15yr = $20K. $10K timing difference.
B34: 4p | C34: Patent Amort Difference (10yr vs 15yr) | F34: 2500 | G34: Temp | H34: Sec 197 | I34: WTB R63. Book 10yr = $7.5K. Tax Sec 197 15yr = $5K. $2.5K timing difference.
B35: 4q | C35: Charitable Contributions (separately stated) | E35: 0 | F35: 25000 | G35: N/A | H35: Sec 170 | I35: WTB R64. $25K reclassed from P1 to K 13a. Not a disallowance; flows to partner for AGI limit.
B36: 4r | C36: Investment Interest (separately stated) | E36: 0 | F36: 3500 | G36: N/A | H36: Sec 163(d) | I36: WTB R65. $3.5K reclassed from P1 to K 13b. Partner applies Sec 163(d) limit.
C37: TOTAL M-1 LINE 4 COMPONENTS | D37: =SUM(D19:D36) | E37: =SUM(E19:E36) | F37: =SUM(F19:F36) | I37: Should approximate M-1 Line 4 tax amount.
A39: PERMANENT vs TEMPORARY DIFFERENCE SUMMARY
C40: Category | D40: Amount
C41: Meals 50%
C42: Entertainment
C43: Club Dues
...

Sheet M-2 Workpaper
A1: SCHEDULE M-2 — PARTNERS' CAPITAL ACCOUNT RECONCILIATION WORKPAPER
A2: [ENTITY NAME] | EIN: [XX-XXXXXXX] | Tax Year Ended: [MM/DD/YYYY]
A4: # | B4: M-2 Line | C4: Description | D4: Book Basis | E4: Tax Basis | F4: IRC / Authority | G4: Detail / WTB Ref
A5: M-2 CAPITAL ACCOUNT RECONCILIATION
A6: 1 | B6: M-2 Line 1 | C6: Balance at Beginning of Year | D6: ='Working Trial Balance'!D106 | E6: ='Working Trial Balance'!H106 | F6: Sec 704(b) | G6: PRIOR YEAR: MANUALLY ENTER from prior year return. WTB Row 106. Book = $1M (A $500K + B $500K). Tax beg cap should come from PY M-2 Line 9 / PY L col (d).
A7: 2 | B7: M-2 Line 2 | C7: Capital Contributed During Year | D7: ='Working Trial Balance'!D107 | E7: ='Working Trial Balance'!H107 | F7: Sec 721/722 | G7: WTB Row 107. A $25K + B $25K = $50K. Cash contributions. Sec 721: no gain recognized on contribution. Verify bank records.
A8: 3 | B8: M-2 Line 3 | C8: Net Income / Income Per Return | D8: ='Working Trial Balance'!D108 | E8: ='Working Trial Balance'!H108 | F8: Sec 704(a) | G8: WTB Row 108. Book = M-1 Line 1 ($674K). Tax = M-1 Line 9 / K total ($1,077K). Difference = all M-1 adjustments.
A9: 4 | B9: M-2 Line 4 | C9: Other Increases (tax-exempt income) | D9: ='Working Trial Balance'!D109 | E9: ='Working Trial Balance'!H109 | F9: Sec 103 / 705(a)(1)(B) | G9: WTB Row 109. Tax: K Line 18a muni interest $3.8K. Increases outside basis per Sec 705(a)(1)(B). Book: $0 (already in book NI).
A10: 5 | B10: M-2 Line 5 | C10: TOTAL (Lines 1 through 4) | D10: ='Working Trial Balance'!D110 | E10: ='Working Trial Balance'!H110 | G10: WTB Row 110.
A11: 6 | B11: M-2 Line 6 | C11: Distributions (Cash and Property) | D11: ='Working Trial Balance'!D111 | E11: ='Working Trial Balance'!H111 | F11: Sec 731 | G11: WTB Row 111. $220K. Must = K Lines 19a-19b. Nontaxable to extent of basis. If excess = gain under Sec 731(a)(1).
A12: 7 | B12: M-2 Line 7 | C12: Other Decreases (nondeductible expenses) | D12: ='Working Trial Balance'!D112 | E12: ='Working Trial Balance'!H112 | F12: Sec 705(a)(2)(B) | G12: WTB Row 112. Tax: K Line 18c = $58.6K total nondeductible. Decreases outside basis per Sec 705(a)(2)(B). Book: $0 (already in book NI).
A13: 8 | B13: M-2 Line 8 | C13: Total Decreases (Lines 6 + 7) | D13: ='Working Trial Balance'!D113 | E13: ='Working Trial Balance'!H113 | G13: WTB Row 113.
A14: 9 | B14: M-2 Line 9 | C14: BALANCE AT END OF YEAR (Line 5 - Line 8) | D14: ='Working Trial Balance'!D114 | E14: ='Working Trial Balance'!H114 | F14: Sec 704(b) | G14: WTB Row 114. Must = L Line 22 and sum of K-1 ending capital accounts.
B16: CHECK | C16: M-2 Line 9 vs L Line 22 (should match) | E16: ='Working Trial Balance'!H114-'Working Trial Balance'!H117 | G16: Should be ZERO. L Line 22 is forced = M-2 Line 9 by formula.
A18: PER-PARTNER CAPITAL ACCOUNT DETAIL (50/50)
C19: Item | D19: Partner A | E19: Partner B
C20: Beginning Capital | D20: ='Working Trial Balance'!H106/2 | E20: ='Working Trial Balance'!H106/2 | G20: PY return
C21: Contributions | D21: ='Working Trial Balance'!H107/2 | E21: ='Working Trial Balance'!H107/2 | G21: Bank records
C22: Share of Income (per return) | D22: ='Working Trial Balance'!H108/2 | E22: ='Working Trial Balance'!H108/2 | G22: K-1 total income
C23: Tax-Exempt Income | D23: ='Working Trial Balance'!H109/2 | E23: ='Working Trial Balance'!H109/2 | G23: K 18a
C24: Distributions | D24: =0-'Working Trial Balance'!H111/2 | E24: =0-'Working Trial Balance'!H111/2 | G24: K 19a
C25: Nondeductible Expenses | D25: =0-'Working Trial Balance'!H112/2 | E25: =0-'Working Trial Balance'!H112/2 | G25: K 18c
C26: Ending Tax Capital (per K-1) | D26: =SUM(D20:D25) | E26: =SUM(E20:E25)
C27: Combined (A + B) = M-2 Line 9? | D27: =D26+E26 | E27: ='Working Trial Balance'!H114
C28: Difference (should be ZERO) | D28: =D27-E27

Sheet M-3 Workpaper
A1: SCHEDULE M-3 (FORM 1065) — NET INCOME RECONCILIATION WORKPAPER
A2: [ENTITY NAME] | EIN: [XX-XXXXXXX] | Tax Year Ended: [MM/DD/YYYY]
A3: Gold = Linked to WTB | Blue font = Manual input | Green = Check/auto | Red = Prior year (manually enter)
A5: PART I — FINANCIAL INFORMATION AND NET INCOME (LOSS) RECONCILIATION
A6: # | B6: M-3 Ref | C6: Description | D6: Amount | H6: Authority | I6: Detail / WTB Ref
A7: 1 | B7: Pt I L1 | C7: Net Income (Loss) per Income Statement | D7: ='Working Trial Balance'!D94 | I7: WTB Row 94. Book net income $674K. Starting point.
A8: 2 | B8: Pt I L2 | C8: Net Income (Loss) of Nonincludible Entities | D8: 0 | I8: None.
A9: 4 | B9: Pt I L4a | C9: Income from Equity Method Foreign Corps | D9: 0 | H9: Sec 902/960 | I9: None.
A10: 5 | B10: Pt I L4b | C10: Income from Equity Method US Corps | D10: 0 | I10: None.
A11: 6 | B11: Pt I L5 | C11: Income from Entity Not Included on Return | D11: 0 | I11: None.
A12: 7 | B12: Pt I L6 | C12: Income from Entity on Return Not on Books | D12: 0 | I12: None.
A13: 8 | B13: Pt I L7 | C13: Income (Loss) of Other Includible Entities | D13: 0 | I13: None.
A14: 9 | B14: Pt I L8 | C14: Adjustment to Reconcile | D14: 0 | I14: Enter if reclasses needed. Usually $0.
A15: 3 | B15: Pt I L3 | C15: Net Income per IS of Includible Entities (L1 - L2) | D15: =D7-D8 | I15: Should = book NI $674K.
A16: 10 | B16: Pt I L9 | C16: Net Income per IS After Adjustments | D16: =D15+SUM(D9:D14) | I16: Flows as col(a) starting point to Part II.
A17: 11 | B17: Pt I L11 | C17: Income Per Return (K Lines 1-11 total) | G17: ='Working Trial Balance'!H82 | I17: WTB Row 82. $1,077,300.
A19: PART II — INCOME AND GAIN ITEMS
A20: # | B20: M-3 Ref | C20: Description | D20: (a) Book Amt | E20: (b) Temp Diff | F20: (c) Perm Diff | G20: (d) Tax Amt | H20: IRC / Authority | I20: Detail / WTB Ref
A21: 1 | B21: Pt II L1 | C21: Net Income (Loss) Per Income Statement | D21: ='Working Trial Balance'!D94 | E21: 0 | F21: 0 | G21: =D21+E21+F21 | I21: Pt I L9 = $674K. All subsequent lines have col(a)=0; diffs go in (b) and (c).
A22: 2 | B22: Pt II L2 | C22: Sec 1245 Ordinary Income Recapture (M-1 L2) | D22: 0 | E22: ='Working Trial Balance'!H95 | F22: 0 | G22: =D22+E22+F22 | H22: Sec 1245 | I22: WTB R95. $12K recapture on disposed equipment. On K, not on books. Temp.
A23: 3 | B23: Pt II L3 | C23: Guaranteed Payments Reclass (M-1 L3) | D23: 0 | E23: ='Working Trial Balance'!H96 | F23: 0 | G23: =D23+E23+F23 | H23: Sec 707(c) | I23: WTB R96. $192K. Deducted in book NI; reclassed to K Line 4c on return. Temp reclass.
A24: 4 | B24: Pt II L4 | C24: Tax-Exempt Interest — On Books, Not on K (M-1 L6) | D24: 0 | E24: 0 | G24: =D24+E24+F24 | H24: Sec 103 | I24: Muni $3.8K in book NI; excluded from taxable. Perm. Flows to K 18a.
A25: 5 | B25: Pt II L5 | C25: COD Income Excluded Sec 108 — On Books, Not on K (M-1 L6) | D25: 0 | E25: 0 | G25: =D25+E25+F25 | H25: Sec 108 | I25: $15K excluded under insolvency. In book NI; not on return. Perm.
C26: PART II TOTAL — INCOME ITEMS | D26: =SUM(D21:D25) | E26: =SUM(E21:E25) | F26: =SUM(F21:F25) | G26: =SUM(G21:G25)
A28: PART III — EXPENSE / DEDUCTION ITEMS
A29: # | B29: M-3 Ref | C29: Description | D29: (a) Book Amt | E29: (b) Temp Diff | F29: (c) Perm Diff | G29: (d) Tax Amt | H29: IRC / Authority | I29: Detail / WTB Ref
A30: 1 | B30: Pt III L1 | C30: Sec 263A UNICAP Adjustment | D30: 0 | F30: 0 | G30: =D30+E30+F30 | H30: Sec 263A | I30: M-1 4a. $8.5K additional COGS capitalization on tax. Temp (reverses when sold).
A31: 2 | B31: Pt III L2 | C31: Related-Party Accrued Comp (Sec 267) | D31: 0 | F31: 0 | G31: =D31+E31+F31 | H31: Sec 267(a)(2) | I31: M-1 4b. $35K accrued on books; deferred on tax until paid. Temp.
A32: 3 | B32: Pt III L3 | C32: Bad Debt — Reserve vs Specific Write-Off | D32: 0 | F32: 0 | G32: =D32+E32+F32 | H32: Sec 166 | I32: M-1 4c. Book reserve $22K; tax specific charge-off $0. Temp.
A33: 4 | B33: Pt III L4 | C33: Meals — 50% Limitation | D33: 0 | E33: 0 | G33: =D33+E33+F33 | H33: Sec 274(n) | I33: M-1 4d. $32K book, $16K tax. $16K perm disallowed to K 18c.
A34: 5 | B34: Pt III L5 | C34: Entertainment — 100% Disallowed | D34: 0 | E34: 0 | G34: =D34+E34+F34 | H34: Sec 274(a)(1) | I34: M-1 4e. Post-TCJA fully nondeductible. Perm to K 18c.
A35: 6 | B35: Pt III L6 | C35: Club Dues — 100% Disallowed | D35: 0 | E35: 0 | G35: =D35+E35+F35 | H35: Sec 274(a)(3) | I35: M-1 4f. Country club $6K. Perm to K 18c.
A36: 7 | B36: Pt III L7 | C36: Penalties and Fines | D36: 0 | E36: 0 | G36: =D36+E36+F36 | H36: Sec 162(f) | I36: M-1 4g. $4.5K. Perm to K 18c.
A37: 8 | B37: Pt III L8 | C37: Political Contributions | D37: 0 | E37: 0 | G37: =D37+E37+F37 | H37: Sec 162(e) | I37: M-1 4h. $2K. Perm to K 18c.
A38: 9 | B38: Pt III L9 | C38: Key Person Life Insurance | D38: 0 | E38: 0 | G38: =D38+E38+F38 | H38: Sec 264(a)(1) | I38: M-1 4i. $9.6K. Partnership beneficiary. Perm to K 18c.
A39: 10 | B39: Pt III L10 | C39: State Income / Franchise Tax | D39: 0 | E39: 0 | G39: =D39+E39+F39 | H39: Sec 275(a)(4) | I39: M-1 4j. $12K. Not deductible on federal return. Perm to K 18c.
A40: 11 | B40: Pt III L11 | C40: Warranty Reserve | D40: 0 | F40: 0 | G40: =D40+E40+F40 | H40: Sec 461(h) | I40: M-1 4k. $15K. Accrued on books; not deductible until economic performance. Temp.
A41: 12 | B41: Pt III L12 | C41: Litigation Reserve | D41: 0 | F41: 0 | G41: =D41+E41+F41 | H41: Sec 461(h) | I41: M-1 4l. $40K. Accrued on books; not deductible until settlement. Temp.
A42: 13 | B42: Pt III L13 | C42: Partner Health Insurance (reclass to K-1) | D42: 0 | E42: 0 | G42: =D42+E42+F42 | H42: Sec 162(l) | I42: M-1 4m. $28K. Not P1 deduction; to K-1 13 Code M. Perm at entity level.
A43: 14 | B43: Pt III L14 | C43: Capital Improvement (Sec 179 reclass) | D43: 0 | F43: 0 | G43: =D43+E43+F43 | H43: Sec 179/263 | I43: M-1 4n. Book expensed $35K. Tax: capitalize + Sec 179 (K L12). Temp/reclass.
...

Sheet Adjustments Workpaper
A1: [ENTITY NAME] — BOOK-TO-TAX ADJUSTMENTS WORKPAPER
A2: EIN: [XX-XXXXXXX] | Tax Year Ended: [MM/DD/YYYY] | Form 1065
A3: LEGEND: Blue font = Manual entry from PBC / depr schedule | Gold fill = Linked to WTB | Green = Auto-calculated | Red = Prior year / manually enter
A5: SECTION A — BOOK-TO-TAX ADJUSTMENTS CHECKLIST
A6: Review each category below. Enter book amounts and adjustments. Tax amount auto-calculates. Hide rows that do not apply to this client.
A8: AJE# | B8: Category | C8: Description / What to Look For | D8: IRC Section | E8: WTB Row | F8: Book Amount | G8: Adjustment (+/-) | H8: Tax Amount | I8: Perm / Temp | J8: M-1 Line | K8: K Line | L8: Preparer Notes / Status
A9: INCOME ADJUSTMENTS
A10: AJE-01 | B10: Depreciation — MACRS vs Book | C10: Compare book depreciation to tax MACRS. Excess MACRS over book increases tax deduction. Get from depreciation schedule. | D10: §167/168 | E10: 44 (P1 L16a) | F10: ='Working Trial Balance'!D44 | G10: ='Working Trial Balance'!F44 | H10: ='Working Trial Balance'!H44 | I10: Temp | J10: 4a / 7 | L10: Enter MACRS from tax depr schedule. Verify assets placed-in-service dates.
A11: AJE-02 | B11: Sec 179 Expense Election | C11: Capital items expensed under Sec 179. Reclassify book expense to asset, then elect Sec 179 on K-1. | D11: §179 | E11: 61 (sub-line) / 84 (K L12) | F11: ='Working Trial Balance'!D61 | G11: =-'Working Trial Balance'!G61 | H11: ='Working Trial Balance'!H61 | I11: Temp | J11: 7 | K11: K 12 | L11: Book expensed $35K. Tax: remove from P1 deductions, elect Sec 179 on K Line 12. Partner applies own limit.
A12: AJE-03 | B12: Sec 1245 Ordinary Recapture | C12: On asset dispositions, recapture gain attributable to depreciation as ordinary income (Form 4797). | D12: §1245 | E12: 33 (P1 L6) | F12: ='Working Trial Balance'!D33 | G12: ='Working Trial Balance'!F33 | H12: ='Working Trial Balance'!H33 | I12: Temp | J12: 2 | L12: Analyze each disposition. Recapture = lesser of gain or total depr taken.
A13: AJE-04 | B13: Sec 1231 Gain Reclassification | C13: Remaining gain on business property held >1yr after Sec 1245 recapture. Separately stated on K. | D13: §1231 | E13: 80 (K L10) | F13: ='Working Trial Balance'!D80 | G13: =-'Working Trial Balance'!G80 | H13: ='Working Trial Balance'!H80 | I13: N/A | K13: K 10 | L13: Check 5-yr lookback for prior Sec 1231 losses.
A14: AJE-05 | B14: COD Income Exclusion (Insolvency) | C14: Cancellation of debt income excluded under Sec 108 if partnership was insolvent at time of discharge. | D14: §108 | E14: 34 (P1 L7) | F14: ='Working Trial Balance'!D34 | G14: =-'Working Trial Balance'!G34 | H14: ='Working Trial Balance'!H34 | I14: Perm | J14: 6 | L14: File Form 982. Reduce tax attributes. Get insolvency documentation.
A15: AJE-06 | B15: Rental Real Estate — Depr Diff | C15: Rental property depreciation difference. Tax depreciation on rental assets vs book. | D15: §167/168 | E15: 71 (K L2) | F15: ='Working Trial Balance'!D71 | G15: ='Working Trial Balance'!F71 | H15: ='Working Trial Balance'!H71 | I15: Temp | J15: 7 | K15: K 2 | L15: Separate depreciation schedule for rental property.
A16: DEDUCTION ADJUSTMENTS — TIMING (TEMPORARY)
A17: AJE-07 | B17: Sec 263A — UNICAP Adjustment | C17: Uniform capitalization — additional costs capitalized into inventory for tax. Compare COGS with/without UNICAP. | D17: §263A | E17: 8 (L L3-5) | F17: ='Working Trial Balance'!D8 | G17: ='Working Trial Balance'!F8 | H17: ='Working Trial Balance'!H8 | I17: Temp | J17: 4c | L17: Required if avg gross receipts >$29M (2025). Calculate using simplified method.
A18: AJE-08 | B18: Sec 267 — Related Party Accrued Expenses | C18: Accrued expenses to related parties (>50% ownership) not deductible until paid. Check if paid within 2.5 months. | D18: §267 | E18: 37 (P1 L9) | F18: ='Working Trial Balance'!D37 | G18: =-'Working Trial Balance'!G37 | H18: ='Working Trial Balance'!H37 | I18: Temp | J18: 4c | L18: Review AP aging for partner/related-party payables. Reverses when paid.
A19: AJE-09 | B19: Bad Debt Reserve vs Specific Charge-Off | C19: Book reserve method not allowed for tax. Only specific charge-offs when debt becomes worthless. | D19: §166 | E19: 40 (P1 L12) | F19: ='Working Trial Balance'!D40 | G19: =-'Working Trial Balance'!G40 | H19: ='Working Trial Balance'!H40 | I19: Temp | J19: 4c | L19: Identify actual write-offs during year. Reserve reverses as accounts are collected/written off.
A20: AJE-10 | B20: Warranty Reserve | C20: Book accrual for estimated warranty costs. Tax: deductible only when economic performance occurs (claims paid). | D20: §461(h) | E20: 58 (sub-line) | F20: ='Working Trial Balance'!D58 | G20: =-'Working Trial Balance'!G58 | H20: ='Working Trial Balance'!H58 | I20: Temp | J20: 4c | L20: Get actual warranty claims paid. Temporary — reverses as claims settle.
A21: AJE-11 | B21: Litigation Reserve / Contingent Liabilities | C21: Book accrual for probable litigation losses. Tax: not deductible until all-events test met and economic performance. | D21: §461(h) | E21: 59 (sub-line) | F21: ='Working Trial Balance'!D59 | G21: =-'Working Trial Balance'!G59 | H21: ='Working Trial Balance'!H59 | I21: Temp | J21: 4c | L21: Review legal correspondence. Settlement or judgment triggers deduction.
A22: AJE-12 | B22: Allowance for Doubtful Accounts (B/S) | C22: Book reserve against A/R. Tax: add back to assets (reserve method not allowed). | D22: §166 | E22: 7 (L L1-2) | F22: ='Working Trial Balance'!D7 | G22: ='Working Trial Balance'!F7 | H22: ='Working Trial Balance'!H7 | I22: Temp | L22: B/S only adjustment. Affects tax basis of receivables. Cross-ref AJE-09.
A23: AJE-13 | B23: Goodwill Amortization (Book 10yr vs Tax 15yr) | C23: Book amortizes goodwill over useful life (often 10yr). Tax: Sec 197 requires 15-year straight-line. | D23: §197 | E23: 62 (sub-line) | F23: ='Working Trial Balance'!D62 | G23: =-'Working Trial Balance'!G62 | H23: ='Working Trial Balance'!H62 | I23: Temp | J23: 4a | L23: Calculate: Cost / 180 months × months. Compare to book amort.
A24: AJE-14 | B24: Patent/Intangible Amortization (Book vs Tax) | C24: Patents and other Sec 197 intangibles. Book life may differ from 15-year tax amortization. | D24: §197 | E24: 63 (sub-line) | F24: ='Working Trial Balance'!D63 | G24: =-'Working Trial Balance'!G63 | H24: ='Working Trial Balance'!H63 | I24: Temp | J24: 4a | L24: Same 15-yr rule applies. Calculate monthly amort × months.
A25: DEDUCTION ADJUSTMENTS — PERMANENT
A26: AJE-15 | B26: Meals — 50% Limitation | C26: Business meals deductible at 50%. Identify total meals expense and disallow half. | D26: §274(n) | E26: 51 (sub-line) | F26: ='Working Trial Balance'!D51 | G26: =-'Working Trial Balance'!G51 | H26: ='Working Trial Balance'!H51 | I26: Perm | J26: 4b | K26: K 18c | L26: Verify meals vs entertainment classification. Must have business purpose documented.
A27: AJE-16 | B27: Entertainment — 100% Nondeductible | C27: Entertainment expenses fully nondeductible post-TCJA. Includes sporting events, theater, etc. | D27: §274(a) | E27: 52 (sub-line) | F27: ='Working Trial Balance'!D52 | G27: =-'Working Trial Balance'!G52 | H27: ='Working Trial Balance'!H52 | I27: Perm | J27: 4b | K27: K 18c | L27: Confirm proper classification. Entertainment ≠ meals.
A28: AJE-17 | B28: Club Dues — Nondeductible | C28: Country club, social club, athletic club dues. Fully nondeductible regardless of business use. | D28: §274(a)(3) | E28: 53 (sub-line) | F28: ='Working Trial Balance'!D53 | G28: =-'Working Trial Balance'!G53 | H28: ='Working Trial Balance'!H53 | I28: Perm | J28: 4c | K28: K 18c
A29: AJE-18 | B29: Penalties & Fines — Nondeductible | C29: Government fines and penalties. Nondeductible unless restitution or compliance payments. | D29: §162(f) | E29: 54 (sub-line) | F29: ='Working Trial Balance'!D54 | G29: =-'Working Trial Balance'!G54 | H29: ='Working Trial Balance'!H54 | I29: Perm | J29: 4c | K29: K 18c | L29: Review GL for penalty accounts. Check if any qualify under exception.
A30: AJE-19 | B30: Political Contributions — Nondeductible | C30: Contributions to political parties, candidates, or PACs. Always nondeductible. | D30: §162(e) | E30: 55 (sub-line) | F30: ='Working Trial Balance'!D55 | G30: =-'Working Trial Balance'!G55 | H30: ='Working Trial Balance'!H55 | I30: Perm | J30: 4c | K30: K 18c
A31: AJE-20 | B31: Life Insurance (Entity Beneficiary) | C31: Premiums on policies where partnership is beneficiary. Nondeductible. | D31: §264(a)(1) | E31: 56 (sub-line) | F31: ='Working Trial Balance'!D56 | G31: =-'Working Trial Balance'!G56 | H31: ='Working Trial Balance'!H56 | I31: Perm | J31: 4c | K31: K 18c | L31: Confirm partnership is beneficiary. Key-person policies.
A32: AJE-21 | B32: State Income/Franchise Tax | C32: State income or franchise taxes paid. Not deductible on federal partnership return. | D32: §275 | E32: 57 (sub-line) | F32: ='Working Trial Balance'!D57 | G32: =-'Working Trial Balance'!G57 | H32: ='Working Trial Balance'!H57 | I32: Perm | J32: 4c | K32: K 18c | L32: Separate from deductible property taxes and payroll taxes.
A33: SEPARATELY STATED / K-1 ITEMS
A34: AJE-22 | B34: Tax-Exempt Interest Income | C34: Municipal bond interest. Not taxable but increases partner basis. Report on K Line 18a. | D34: §103 | E34: 88 (K L18a) | F34: ='Working Trial Balance'!D88 | G34: 0 | H34: ='Working Trial Balance'!H88 | I34: Perm | J34: 6 | K34: K 18a | L34: Include in M-2 other increases. Increases basis.
A35: AJE-23 | B35: Partner Health Insurance (to K-1) | C35: Health insurance premiums for partners. Not a P1 deduction — goes to each K-1 Line 13 Code M. | D35: §162(l) | E35: 60 (sub-line) | F35: ='Working Trial Balance'!D60 | G35: =-'Working Trial Balance'!G60 | H35: ='Working Trial Balance'!H60 | I35: N/A | J35: 4c | K35: K-1 13M | L35: Allocate per partner. Partner takes as SE health ins deduction on 1040.
A36: AJE-24 | B36: Charitable Contributions (to K-1) | C36: Charitable donations. Separately stated — not on P1. Each partner applies own AGI limitation. | D36: §170 | E36: 64 (sub-line) | F36: ='Working Trial Balance'!D64 | G36: =-'Working Trial Balance'!G64 | H36: ='Working Trial Balance'!H64 | I36: N/A | J36: 4c | K36: K 13a | L36: Get donation receipts for >$250. Noncash >$500 needs Form 8283.
A37: AJE-25 | B37: Investment Interest Expense (to K-1) | C37: Interest on debt to carry investments. Separately stated — partner applies Sec 163(d) limitation. | D37: §163(d) | E37: 65 (sub-line) | F37: ='Working Trial Balance'!D65 | G37: =-'Working Trial Balance'!G65 | H37: ='Working Trial Balance'!H65 | I37: N/A | J37: 4c | K37: K 13b | L37: Match to investment income. Partner nets on Form 4952.
A39: CHECKLIST TOTALS | F39: =SUM(F9:F37) | G39: =SUM(G9:G37) | H39: =SUM(H9:H37)
A40: CHECK: Net Adjustment (Tax Total - Book Total) should match sum of Adj column | G40: =H39-F39-G39
A43: SECTION B — ADJUSTING JOURNAL ENTRIES (AJEs)
A44: Each AJE represents a book-to-tax adjustment. DR increases tax amount, CR decreases. These entries bridge the gap between client books and the tax return.
A46: AJE# | B46: Date | C46: Account / Line Description | D46: WTB Row | E46: DR (+) | F46: CR (-) | G46: Net Effect | H46: Perm / Temp | I46: IRC Reference | J46: Memo / Workpaper Reference
...

Sheet Tax Strategies Workpaper
A1: TAX STRATEGIES WORKPAPER — 1065 ENTITY-LEVEL STRATEGIES
A2: Strategies that create adjustments on the Form 1065 partnership return. Hide sections not applicable to client.
A3: LEGEND: Blue = Manual entry | Gold = Linked to WTB | Green = Auto-calc | Orange = Adjustment row
A5: 1. AUGUSTA RULE — IRC §280A(g) (14-Day Home Rental to Entity)
A7: FIRM PARAMETERS
B8: Criteria | C8: Amount / Rule | K8: Notes
B9: Income > $1M/yr | C9: $2,000/day × 14 days = $28,000 max | K9: Must own primary residence (not leased)
B10: Income < $1M/yr | C10: $1,000/day × 14 days = $14,000 max | K10: Must own primary residence (not leased)
B11: Eligible entities | C11: Multi-member LLCs, S-Corps, C-Corps | K11: NOT sole prop or Single Member LLC
B12: Documentation | C12: Lease, FMV comps, agendas, minutes, attendee list | K12: Payment trail from entity to member
A14: 1065 ADJUSTMENTS
A15: # | B15: 1065 Line | C15: Description | D15: Book Amt | E15: Tax Adj | F15: Tax Amt | G15: M-1 Line | H15: K Line | I15: WTB Row | J15: AJE Ref | K15: How to Handle
A16: 1 | B16: P1 L20 (Other Ded) | C16: Augusta Rule rent — deduction to partnership | D16: If on books | E16: If not on books | F16: Auto | G16: None if on books. M-1 L7 if tax-only. | H16: Reduces OBI (K L1) | I16: Row 50 | J16: New | K16: If client books the rent expense → flows through P1 L20 naturally, no M-1 adj. If tax-only deduction (not on books) → WTB Row 50 Adj(+), M-1 Line 7 "deduction on return not on books." Either way: reduces OBI → reduces each partner K-1 Box 1.
A17: 2 | B17: Partner (not on 1065) | C17: Partner receives rent — TAX FREE under §280A(g) | K17: Partner does NOT report rental income anywhere. Excluded from gross income. No Schedule E, no 1099-MISC required. Some practitioners issue 1099 and zero out on Sch E — either works.
A19: DOCUMENTATION CHECKLIST
A20: ☐ | B20: Written lease agreement (partnership ↔ member) | J20: Entity file
A21: ☐ | B21: FMV analysis — comparable venue rates (hotels, Airbnb, conference centers) | J21: Entity file
A22: ☐ | B22: Meeting agendas for each of the ≤14 rental days | J22: Entity file
A23: ☐ | B23: Meeting minutes/notes with business decisions documented | J23: Entity file
A24: ☐ | B24: Attendee list per meeting | J24: Entity file
A25: ☐ | B25: Day-count calendar (running total of days used YTD) | J25: Entity file
A26: ☐ | B26: Payment proof — check/wire/ACH from entity account to member personal account | J26: Entity file
A27: ☐ | B27: Partner resolution authorizing the rental arrangement | J27: Entity file
A28: ☐ | B28: Confirm member OWNS primary residence (deed/mortgage statement — strategy fails if leased) | J28: Entity file
A30: 2. KIDS ON PAYROLL / MANAGEMENT COMPANY — IRC §3121(b)(3)(A)
A32: FIRM PARAMETERS
B33: Criteria | C33: Amount / Rule | K33: Notes
B34: Max per child | C34: $16,100/child (2026 standard deduction) | K34: Child owes $0 federal income tax if wages ≤ this
B35: FICA exempt | C35: Child under 18, partnership = both parents only | K35: Any non-parent partner → full FICA applies
B36: FUTA exempt | C36: Child under 21, same ownership rule | K36: Still must file W-2 and 941s even if exempt
B37: Mgmt Co option | C37: Combine Mgmt Co + Kids Payroll when possible | K37: Mgmt Co invoices partnership; pays kids from Mgmt Co
B38: Work must be real | C38: Filing, cleaning, social media, data entry, inventory | K38: Document hours, duties, pay rate
A40: 1065 ADJUSTMENTS
A41: # | B41: 1065 Line | C41: Description | D41: Book Amt | E41: Tax Adj | F41: Tax Amt | G41: M-1 Line | H41: K Line | I41: WTB Row | J41: AJE Ref | K41: How to Handle
A42: 1 | B42: P1 L9 (Salaries) | C42: Wages to partner's child(ren) | D42: If on books | E42: If not on books | F42: Auto | G42: None if on books. M-1 L7 if tax-only. | H42: Reduces OBI (K L1) | I42: Row 37 | J42: New | K42: If wages on client books → no M-1 adj, flows through P1 L9. If tax-only → WTB Row 37 Adj(+), M-1 Line 7. Issue W-2 to child. File 941s quarterly. FICA exempt boxes on W-2 if both-parent partnership and child <18.
A43: 2 | B43: P1 L9 (Salaries) | C43: Employer payroll taxes (if FICA applies) | I43: Row 42 (Taxes) | K43: If FICA exempt: $0 employer FICA. Only FUTA ($42/child max). If NOT exempt (non-parent partner exists): employer pays 7.65% FICA on wages. Payroll tax expense goes to P1 L14 (Taxes and Licenses).
A44: 3 | B44: P1 L20 (Other Ded) | C44: Mgmt Co fees (if using Mgmt Co structure) | D44: If on books | E44: If not on books | F44: Auto | G44: None if on books. M-1 L7 if tax-only. | H44: Reduces OBI (K L1) | I44: Row 50 | J44: New | K44: Partnership pays management fee to separate Mgmt Co (owned by spouse/family). Mgmt Co then pays kids as W-2 employees. Partnership deducts as management fees on P1 L20 Other Deductions. Must be arm's length — reasonable for services rendered.
A46: DOCUMENTATION CHECKLIST
A47: ☐ | B47: Written job description per child — specific duties, responsibilities | J47: Entity file
A48: ☐ | B48: Time sheets / work log signed by child and supervising partner | J48: Entity file
...
