Workbook

Sheet Instructions
A1: 1120-S WORKING TRIAL BALANCE TEMPLATE
A2: Version 1.0
A4: HOW TO USE THIS TEMPLATE
A6: STEP 1: PASTE PBC DATA
A7: • Export P&L from QuickBooks → paste into "PBC - P&L2" tab
A8: • Export Balance Sheet from QuickBooks → paste into "PBC- Balance Sheet" tab
A9: • Make sure Net Income lands in PBC-P&L2 cell B63
A10: • Make sure Total Equity lands in PBC-BS cell B88, Total L&E in B89
A12: STEP 2: BUILD WORKING P&L & BALANCE SHEET
A13: • Map QuickBooks line items to Working P&L (P&L tab, column B) — yellow cells
A14: • Map QuickBooks line items to Working Balance Sheet (Balance Sheet tab) — yellow cells
A15: • Subtotals and totals auto-calculate via formulas
... A63: 13. Schedule M-3 Net income reconciliation (if needed)

Sheet P&L
A1: [ENTITY NAME] — Working Profit & Loss
A2: Profit & Loss — December 1, 2024 to November 30, 2025
A3: Provided by Client (PBC) — QuickBooks Export
A5: Account | B5: Amount
A6: REVENUE
A7: Software Licensing Revenue
A8: —
A9: Equipment Rental Income
A10: Returns & Allowances
A11: Total Revenue | B11: =SUM(B7:B10)
A12: COST OF GOODS SOLD
A13: 5000 · COGS (N/A — service company)
A14: —
A15: —
A16: Total COGS | B16: =SUM(B13:B15)
A17: GROSS PROFIT | B17: =B11-B16
A18: OPERATING EXPENSES
A19: 02 Payroll – Wages & Salaries (all staff)
A20: 02 Payroll – Bonus
A21: 02 Payroll – Health Insurance
A22: 02 Payroll – Payroll Taxes (FICA/FUTA)
A23: 02 Payroll – 401K Retirement Program
A24: 02 Payroll – Payroll Processing Fees
A25: 03 IT – Computer Software & Supplies
A26: 04 Leases – 540 NE 4th Street LLC
A27: —
A28: —
A29: —
... A49: Travel Meals
A50: Total Operating Expenses | B50: =SUM(B19:B49)
A51: OPERATING INCOME | B51: =B17-B50
A52: OTHER INCOME / (EXPENSE)
A53: Interest Income (Schwab & Bank Accounts)
A54: ST Investment Income (Dividends – Schwab)
A55: ↳ Qualified Dividends: TBD (memo — need 1099-DIV)
A56: Capital Gain / (Loss) on Investments
A57: —
A58: —
A59: —
A60: Tax-Exempt Interest
...

Sheet  Balance Sheet
A1: [ENTITY NAME] — Working Balance Sheet
A2: Tax Year Ended [MM/DD/YYYY]
A3: Provided by Client (PBC) — QuickBooks Export
A5: Account | B5: November 30, 2025 | C5: November 30, 2024 (PY) ⚠ MANUALLY ENTER / VERIFY
A6: ASSETS
A7: Current Assets
A8: Cash – Chase 7884 / Chase Operating – 1180 / Wells Fargo – 6016
A9: Intercompany Receivable – IPS (net)
A10: Loans Receivable – Stockholder
A11: Prepaid Expenses
A12: —
A13: —
A14: —
A15: Total Current Assets | B15: =SUM(B8:B14) | C15: =SUM(C8:C14)
A17: Investments
A18: S-T Investments – Schwab One 2480-2532
A19: —
A20: Total Investments | B20: =SUM(B18:B19) | C20: =SUM(C18:C19)
A22: Fixed Assets
A23: Office & Computer Equipment (gross)
A24: Accumulated Depreciation – Office & Computer Equipment
A25: —
A26: —
A27: —
A28: —
A29: —
A30: —
A31: Total Fixed Assets | B31: =SUM(B23:B30) | C31: =SUM(C23:C30)
A33: Other Assets
A34: Security Deposit
A35: L-T Investments (VFT Global + IPS Mexico)
A36: Total Other Assets | B36: =SUM(B34:B35) | C36: =SUM(C34:C35)
A38: TOTAL ASSETS | B38: =B15+B20+B31+B36 | C38: =C15+C20+C31+C36
A40: LIABILITIES
A41: Current Liabilities
A42: Accounts Payable
A43: —
A44: Payroll Liabilities (401K ADP + Payroll Expense Liability)
A45: Accrued Expenses
A46: —
...

Sheet PBC- Balance Sheet
A1: PASTE CLIENT BALANCE SHEET FROM QUICKBOOKS HERE
A2: Column A = Account Name, Column B = Current Year, Column C = Prior Year
A3: Row 88: Total Equity, Row 89: Total L&E (referenced by M-2 formulas)
B88: Total Equity
B89: Total L&E

Sheet PBC - P&L2
A1: PASTE CLIENT P&L FROM QUICKBOOKS HERE
A2: Column A = Account Name, Column B = Amount (Current Year)
A3: Row 63: Net Income (this cell is referenced by formulas)
B63: Net Income goes here

Sheet Working Trial Balance
A1: [ENTITY NAME] — 1120-S Working Trial Balance
A2: Tax Year Ended [MM/DD/YYYY]
A3: Prepared by: ____________ Reviewed by: ____________ Date: ____________
A5: Account Description | B5: A PBC / Book (As Provided) | C5: B Pre-Book Reclass Adj | D5: C = A+B Adjusted Book (Post-Reclass) | E5: D Schedule K Adjustments | F5: E = C+D Tax Return Amount | G5: Ties To (Tax Return Line) | H5: F M-1 Adjustments | I5: M-1 Line Ref | J5: Notes / Explanation
A6: LEGEND: ■ Yellow = M-1 adjustment ■ Green = Separately stated (→ Sch K) ■ Orange = Nondeductible ■ Purple = Basis-affecting (AAA/OAA) ■ Red = Prior-year / Manually Enter
A7: ASSETS (from PBC Balance Sheet — Sch L)
A8: 1000 · Cash - Business Checking | B8: =' Balance Sheet'!B8 | C8: 0 | D8: =B8+C8 | F8: =D8 | G8: Sch L, Ln 1
A9: 1010 · Cash - Business Savings | B9: =' Balance Sheet'!B9 | D9: =B9+C9 | F9: =D9 | G9: Sch L, Ln 1
A10: 1020 · Accounts Receivable | B10: =' Balance Sheet'!B10 | C10: 0 | D10: =B10+C10 | F10: =D10 | G10: Sch L, Ln 5a
A11: 1030 · Allowance for Doubtful Accounts | B11: =' Balance Sheet'!B11 | C11: 0 | D11: =B11+C11 | F11: =D11 | G11: Sch L, Ln 5b
A12: 1040 · Prepaid Expenses | B12: =' Balance Sheet'!B12 | C12: 0 | D12: =B12+C12 | F12: =D12 | G12: Sch L, Ln 6
A13: 1050 · Employee Advances | B13: =' Balance Sheet'!B13 | C13: 0 | D13: =B13+C13 | F13: =D13 | G13: Sch L, Ln 6
A14: 1060 · Inventory | B14: =' Balance Sheet'!B14 | C14: 0 | D14: =B14+C14 | F14: =D14 | G14: Sch L, Ln 7
A15: Total Current Assets | B15: =SUM(B8:B14) | C15: =SUM(C8:C14) | D15: =SUM(D8:D14) | F15: =SUM(F8:F14) | G15: Sch L, Ln 1-7 | H15: =SUM(H8:H14)
A17: 1100 · Brokerage Account | B17: =' Balance Sheet'!B18 | C17: 0 | D17: =B17+C17 | F17: =D17 | G17: Sch L, Ln 8 | J17: Book FMV — may differ from tax basis if unrealized gains.
A18: 1110 · Municipal Bond Portfolio | B18: =' Balance Sheet'!B19 | C18: 0 | D18: =B18+C18 | F18: =D18 | G18: Sch L, Ln 8 | J18: Tax-exempt bonds — interest flows to Sch K Ln 16a.
A19: Total Investments | B19: =SUM(B17:B18) | C19: =SUM(C17:C18) | D19: =SUM(D17:D18) | F19: =SUM(F17:F18) | G19: Sch L, Ln 8 | H19: =SUM(H17:H18)
A21: 1200 · FF&E (Cost) | B21: =' Balance Sheet'!B23 | C21: 0 | D21: =B21+C21 | F21: =D21 | G21: Sch L, Ln 10a
A22: 1201 · Accum Depr - FF&E | B22: =' Balance Sheet'!B24 | C22: 0 | D22: =B22+C22 | F22: =D22 | G22: Sch L, Ln 10b | J22: Book accum depr — tax accum depr may differ (MACRS)
A23: 1210 · Computer Equipment (Cost) | B23: =' Balance Sheet'!B25 | C23: 0 | D23: =B23+C23 | F23: =D23 | G23: Sch L, Ln 10a
A24: 1211 · Accum Depr - Computers | B24: =' Balance Sheet'!B26 | C24: 0 | D24: =B24+C24 | F24: =D24 | G24: Sch L, Ln 10b
A25: 1220 · Leasehold Improvements (Cost) | B25: =' Balance Sheet'!B27 | C25: 0 | D25: =B25+C25 | F25: =D25 | G25: Sch L, Ln 10a
A26: 1221 · Accum Depr - LHI | B26: =' Balance Sheet'!B28 | C26: 0 | D26: =B26+C26 | F26: =D26 | G26: Sch L, Ln 10b
A27: 1230 · Vehicles (Cost) | B27: =' Balance Sheet'!B29 | C27: 0 | D27: =B27+C27 | F27: =D27 | G27: Sch L, Ln 10a
A28: 1231 · Accum Depr - Vehicles | B28: =' Balance Sheet'!B30 | C28: 0 | D28: =B28+C28 | F28: =D28 | G28: Sch L, Ln 10b | J28: Listed property — verify >50% business use.
A29: Total Fixed Assets (Net) | B29: =SUM(B21:B28) | C29: =SUM(C21:C28) | D29: =SUM(D21:D28) | F29: =SUM(F21:F28) | G29: Sch L, Ln 10c | H29: =SUM(H21:H28)
A31: 1300 · Security Deposits | B31: =' Balance Sheet'!B34 | C31: 0 | D31: =B31+C31 | F31: =D31 | G31: Sch L, Ln 13
A32: 1310 · Organizational Costs (Net) | B32: =' Balance Sheet'!B35 | C32: 0 | D32: =B32+C32 | F32: =D32 | G32: Sch L, Ln 13 | J32: §248 amortization. Verify remaining balance.
A33: Total Other Assets | B33: =SUM(B31:B32) | C33: =SUM(C31:C32) | D33: =SUM(D31:D32) | F33: =SUM(F31:F32) | G33: Sch L, Ln 13 | H33: =SUM(H31:H32)
A35: TOTAL ASSETS | B35: =B15+B19+B29+B33 | C35: =C15+C19+C29+C33 | D35: =D15+D19+D29+D33 | F35: =F15+F19+F29+F33 | G35: Sch L, Ln 15
A37: LIABILITIES (from PBC Balance Sheet — Sch L)
A38: 2000 · Accounts Payable | B38: =' Balance Sheet'!B42 | C38: 0 | D38: =B38+C38 | F38: =D38 | G38: Sch L, Ln 16
A39: 2010 · Accrued Expenses | B39: =' Balance Sheet'!B43 | C39: 0 | D39: =B39+C39 | F39: =D39 | G39: Sch L, Ln 18
A40: 2020 · Payroll Liabilities | B40: =' Balance Sheet'!B44 | C40: 0 | D40: =B40+C40 | F40: =D40 | G40: Sch L, Ln 18
A41: 2030 · Credit Card Payable | B41: =' Balance Sheet'!B45 | C41: 0 | D41: =B41+C41 | F41: =D41 | G41: Sch L, Ln 18
A42: 2040 · Sales Tax Payable | B42: =' Balance Sheet'!B46 | C42: 0 | D42: =B42+C42 | F42: =D42 | G42: Sch L, Ln 18
A43: 2050 · Current Portion - Vehicle Loan | B43: =' Balance Sheet'!B47 | C43: 0 | D43: =B43+C43 | F43: =D43 | G43: Sch L, Ln 17
A44: Other liabilities | B44: =' Balance Sheet'!B51 | D44: =B44+C44 | F44: =D44 | G44: Sch L, Ln 19 | J44: Check §163(j) interest limitation.
A45: 2110 · Vehicle Loan (Net of Current) | B45: =' Balance Sheet'!B52 | C45: 0 | D45: =B45+C45 | F45: =D45 | G45: Sch L, Ln 19
A46: 2120 · Shareholder Loan - Principal Shareholder | B46: =' Balance Sheet'!B53 | C46: 0 | D46: =B46+C46 | F46: =D46 | G46: Sch L, Ln 19 | J46: Debt basis for loss limitation. Document loan terms.
...

Sheet Adjusting Entries
A1: [ENTITY NAME] — Adjusting Journal Entries
A2: Form 1120-S / 1065 — Tax Year Ended November 30, 2025
A3: [ENTITY NAME] — EIN: [XX-XXXXXXX]
A4: Each AJE represents one adjustment from the client's books (PBC) to the tax return. Yellow = document you need from client or workpapers. Green = verified/complete.
A6: AJE # | B6: Adjustment Description | C6: PBC Account / Reference | D6: Document Needed (Get This →) | E6: DR Amount | F6: CR Amount | G6: Net Effect on Taxable Inc | H6: Ties To (Return Line) | I6: WTB Row | J6: Status / Preparer Notes
B7: SECTION 1: SEPARATELY STATED INCOME ITEMS (Book → Schedule K)
A8: AJE-01 | B8: Reclassify equipment rental income to Sch K Ln 3 | C8: 4020 · Equipment Rental PBC P&L r9 | D8: Rental agreement / lease contract showing rental activity. Need to split gross income ($85K) and expenses ($35K) for K Ln 3a/3b. | E8: =IF('Strategy Inputs'!C7<>"",'Strategy Inputs'!C7,'Strategy Inputs'!D7) | F8: =E8 | G8: 0 | H8: Sch K Ln 3a (income) Sch K Ln 3b (expenses) | I8: WTB r66 | J8: Reclass only — removes from Pg 1 gross receipts, moves to K Ln 3. Net effect on taxable income = $0. Also need rental expense detail for Ln 3b ($35K). Verify rental is equipment, NOT real estate (real estate → Form 8825).
A9: AJE-02 | B9: Reclassify interest income to Sch K Ln 4 | C9: 7000 · Interest Income PBC P&L r53 | D9: 1099-INT from bank(s). Verify amount matches PBC. If multiple banks, sum all 1099-INTs. | E9: =IF('Strategy Inputs'!C9<>"",'Strategy Inputs'!C9,'Strategy Inputs'!D9) | F9: =E9 | G9: 0 | H9: Sch K Ln 4 / K-1 Box 4 | I9: WTB r68 | J9: Reclass from other income to separately stated. Must match 1099-INT(s). If client has multiple bank accounts, reconcile each.
A10: AJE-03 | B10: Reclassify dividend income to Sch K Ln 5a/5b | C10: 7010 · Dividend Income PBC P&L r54 | D10: 1099-DIV from brokerage. CRITICAL: Need Box 1b (qualified dividends) for K Ln 5b. Total ordinary = Ln 5a, qualified subset = Ln 5b. | E10: =IF('Strategy Inputs'!C10<>"",'Strategy Inputs'!C10,'Strategy Inputs'!D10) | F10: =E10 | G10: 0 | H10: Sch K Ln 5a (total) Sch K Ln 5b (qualified) | I10: WTB r69 | J10: Ordinary dividends = $8,500 (Ln 5a). Qualified = $6,800 (Ln 5b — verify against 1099-DIV Box 1b). Qualified must be ≤ ordinary.
A11: AJE-04 | B11: Reclassify LTCG to Sch K Ln 8a | C11: 7020 · Capital Gain PBC P&L r56 | D11: 1099-B from brokerage + Form 8949 / Schedule D. Need: purchase date, sale date, proceeds, cost basis for EACH transaction. Verify LTCG (held >1 yr). | E11: =IF('Strategy Inputs'!C12<>"",'Strategy Inputs'!C12,'Strategy Inputs'!D12) | F11: =E11 | G11: 0 | H11: Sch K Ln 8a / Sch D Form 8949 | I11: WTB r70 | J11: $12K net LTCG. Need 1099-B for each sale. If any STCG, separate to K Ln 7. Watch for wash sale adjustments (1099-B Box 1g).
A12: AJE-05 | B12: Adjust equipment sale gain: book → tax (§1231/§1245 split) | C12: 7030 · Gain on Sale PBC P&L r57 | D12: Form 4797 + Fixed asset schedule. Need: original cost, date placed in service, date sold, sale price, tax accum depr (MACRS). §1245 recapture portion vs §1231 gain. | E12: =IF('Strategy Inputs'!C13<>"",'Strategy Inputs'!C13,'Strategy Inputs'!D13) | F12: =E12 | G12: =E12-F12 | H12: Form 4797 Sch K Ln 9 (§1231) Pg 1 Ln 4 (§1245) | I12: WTB r71 | J12: Book gain $15K. Tax split: $10K §1245 recapture (stays on Pg 1) + $5K §1231 gain (→ K Ln 9). Need TAX cost basis and TAX accum depr — book depr differs from MACRS. Form 4797 required.
B13: SECTION 2: NONDEDUCTIBLE EXPENSES (Book Expense → $0 or Partial on Return)
A14: AJE-06 | B14: >2% Shareholder health insurance — remove from Pg 1 deductions | C14: 6031 · Officer Health Ins PBC P&L r24 | D14: Health insurance invoices/premiums paid for >2% SHs. Amount must be added to officers' W-2 Box 1. Verify W-2 includes this amount. Officers deduct on personal 1040 Ln 17. | E14: =IF('Strategy Inputs'!C20<>"",'Strategy Inputs'!C20,'Strategy Inputs'!D20) | F14: 0 | G14: =E14 | H14: M-1 Ln 3b K Ln 16c (nondeductible) W-2 Box 1 | I14: WTB r91 | J14: NOT deducted on 1120-S. Added to officer W-2 Box 1 (not Box 12, Code DD). Officer deducts on personal 1040 Schedule 1, Line 17. Verify payroll company added it correctly.
A15: AJE-07 | B15: Meals — 50% disallowance (book $18K → tax deduction $9K) | C15: 6300 · Business Meals PBC P&L r32 | D15: Meal receipts / expense reports. Verify ALL are business meals with business purpose documented (who, what, where, why). Restaurant vs non-restaurant distinction no longer matters post-2022. | E15: =IF('Strategy Inputs'!C21<>"",'Strategy Inputs'!C21,'Strategy Inputs'!D21) | F15: 0 | G15: =E15 | H15: Pg 1 Ln 19 (50% deductible) M-1 Ln 3c (50% addback) K Ln 16c (nondeductible) | I15: WTB r99 | J15: $18K book × 50% = $9K deductible on Pg 1 Ln 19 + $9K nondeductible on M-1/K Ln 16c. The 50% deductible portion stays on Pg 1. The 50% disallowed is the M-1 addback.
A16: AJE-08 | B16: Entertainment — 100% disallowed (book $12K → tax $0) | C16: 6310 · Entertainment PBC P&L r33 | D16: Entertainment receipts. Verify client properly separates meals AT entertainment events (those meals ARE 50% deductible). Pure entertainment = 100% nondeductible post-TCJA. | E16: =IF('Strategy Inputs'!C22<>"",'Strategy Inputs'!C22,'Strategy Inputs'!D22) | F16: 0 | G16: =E16 | H16: M-1 Ln 3d K Ln 16c (nondeductible) | I16: WTB r100 | J16: $0 on return. Full addback. Ask client: did any "entertainment" include separately invoiced food? If so, food portion is 50% deductible.
A17: AJE-09 | B17: Charitable contributions — remove from Pg 1, separately state on K Ln 12a | C17: 6900 · Charitable PBC P&L r45 | D17: Donation receipts / acknowledgment letters. Cash >$250 needs written acknowledgment. Noncash >$500 needs Form 8283. Verify all are to qualified §501(c)(3) organizations. | E17: =IF('Strategy Inputs'!C17<>"",'Strategy Inputs'!C17,'Strategy Inputs'!D17) | F17: 0 | G17: =E17 | H17: K Ln 12a / K-1 Box 12A M-1 Ln 3e | I17: WTB r114 | J17: ADDBACK — removed from entity Pg 1 deductions. Separately stated on K Ln 12a, flows to SH personal Sch A. From M-1 perspective, this is a Ln 3 addback. SH deducts on personal return subject to AGI limits.
A18: AJE-10 | B18: Political contributions — 100% nondeductible | C18: 6910 · Political PBC P&L r46 | D18: Cancelled checks / bank statements showing payment to political organizations, PACs, lobbying firms. No supporting receipt needed — just verify amounts. | E18: =IF('Strategy Inputs'!C23<>"",'Strategy Inputs'!C23,'Strategy Inputs'!D23) | F18: 0 | G18: =E18 | H18: M-1 Ln 3f K Ln 16c (nondeductible) | I18: WTB r115 | J18: $0 on return. §162(e) — political and lobbying expenses are permanently nondeductible. Reduces SH basis via K Ln 16c.
A19: AJE-11 | B19: Penalties & fines — 100% nondeductible | C19: 6920 · Penalties PBC P&L r47 | D19: Penalty notices / invoices. Check if any are "restitution" payments — those MAY be deductible under §162(f) exception. Get the actual notice to determine. | E19: =IF('Strategy Inputs'!C24<>"",'Strategy Inputs'!C24,'Strategy Inputs'!D24) | F19: 0 | G19: =E19 | H19: M-1 Ln 3g K Ln 16c | I19: WTB r116 | J19: §162(f) — fines/penalties paid to government for violation of law = nondeductible. Exception: amounts for restitution or compliance. Get the actual penalty letter.
A20: AJE-12 | B20: Life insurance premiums (corp beneficiary) — nondeductible | C20: 6930 · Life Insurance PBC P&L r48 | D20: Insurance policy + premium statement. CRITICAL: Verify corp is beneficiary (not SH). If SH is beneficiary, it's compensation — different treatment entirely (add to W-2). | E20: =IF('Strategy Inputs'!C25<>"",'Strategy Inputs'!C25,'Strategy Inputs'!D25) | F20: 0 | G20: =E20 | H20: M-1 Ln 3h K Ln 16c | I20: WTB r117 | J20: §264(a)(1) — premiums on policies where corp is beneficiary are nondeductible. If proceeds received, they're tax-exempt (§101) → K Ln 16b / OAA.
A21: AJE-13 | B21: Club dues (country club) — nondeductible | C21: 6940 · Club Dues PBC P&L r49 | D21: Club membership invoices / statements. NOTE: meals consumed at the club are SEPARATELY deductible at 50%. Ask client to split if not already separated in books. | E21: =IF('Strategy Inputs'!C26<>"",'Strategy Inputs'!C26,'Strategy Inputs'!D26) | F21: 0 | G21: =E21 | H21: M-1 Ln 3i K Ln 16c | I21: WTB r118 | J21: §274(a)(3) — club dues nondeductible since 1993. Country clubs, social clubs, athletic clubs, airline clubs. Ask: any separate meal charges billed by the club?
B22: SECTION 3: DEPRECIATION — BOOK TO TAX (Most Common Adjustment)
A23: AJE-14 | B23: Remove ALL book depreciation (replaced by tax MACRS) | C23: 6510-6620 · Book Depr PBC P&L r38-41 | D23: Book depreciation schedule / fixed asset report from client's accounting system. Verify total matches PBC: Vehicle $8K + FF&E $22K + Computers $18K + LHI $12K = $60K. | E23: =IF('Strategy Inputs'!C29<>"",'Strategy Inputs'!C29,'Strategy Inputs'!D29) | F23: 0 | G23: =E23 | H23: M-1 Ln 3a (addback) Removed from Pg 1 | I23: WTB r105-108 | J23: Book SL depr is REMOVED. Tax MACRS (AJE-15) replaces it. Net difference = M-1 adjustment. Verify book schedule ties to PBC exactly.
A24: AJE-15 | B24: Add tax depreciation — MACRS / bonus (Form 4562) | C24: Form 4562 Tax depr software | D24: Form 4562 (Depreciation & Amortization). Run tax depreciation software (CCH, Lacerte, UltraTax). Need asset-by-asset detail: cost, date in service, method (200DB/150DB/SL), convention, life, prior depr. | E24: 0 | F24: ='Strategy Inputs'!C30 | H24: Form 4562 Pg 1 Ln 14 M-1 Ln 6a | I24: WTB r109 | J24: $75K MACRS replaces $60K book depr. Net extra deduction = $15K. AJE-14 + AJE-15 together = net depreciation timing difference. Form 4562 is the support.
A25: AJE-16 | B25: §179 immediate expensing (Form 4562 Part I) | C25: Form 4562 Part I Election on return | D25: Form 4562 Part I. Asset must be §179 eligible (tangible personal property, off-the-shelf software, qualified improvement property). Need asset ID, cost, date placed in service. | E25: 0 | F25: ='Strategy Inputs'!C31 | H25: K Ln 11 / K-1 Box 11 Form 4562 Part I M-1 Ln 6b | I25: WTB r110 | J25: $17K §179. Separately stated on K (not on Pg 1). Subject to business income limitation at SH level. 2024 limit = $1,220,000. Phase-out begins at $3,050,000.
B26: SECTION 4: TAX-EXEMPT & BOOK-ONLY ITEMS (Remove from Taxable Income)
A27: AJE-17 | B27: Tax-exempt municipal bond interest — remove from taxable income | C27: 7200 · Tax-Exempt Muni PBC P&L r60 | D27: 1099-INT Box 8 (tax-exempt interest) from brokerage / bond custodian. Also check Box 9 for AMT-specific muni interest (private activity bonds). | E27: =IF('Strategy Inputs'!C15<>"",'Strategy Inputs'!C15,'Strategy Inputs'!D15) | F27: 0 | G27: =-E27 | H27: K Ln 16a / K-1 Box 16A M-1 Ln 5a M-2 → OAA | I27: WTB r72 | J27: On books as income, NOT on tax return. Increases SH basis (7203) and goes to OAA (not AAA) on M-2. Verify against 1099-INT Box 8.
A28: AJE-18 | B28: Unrealized gain on investments — remove (book only, not realized for tax) | C28: 7300 · Unrealized Gain PBC P&L r61 | D28: Brokerage statement showing beginning vs ending market value. Verify this is unrealized (not sold). If client uses mark-to-market accounting, need year-end portfolio valuation. | E28: =IF('Strategy Inputs'!C16<>"",'Strategy Inputs'!C16,'Strategy Inputs'!D16) | F28: 0 | G28: =-E28 | H28: M-1 Ln 5b No return line | I28: WTB r73 | J28: GAAP requires mark-to-market; tax doesn't recognize until sold. This reverses when positions are eventually sold. Track cumulative unrealized for Sch L book vs tax difference.
B30: SECTION 5: ADDITIONAL DOCUMENTS NEEDED (Not AJEs — Support for Return)
A31: DOC-01 | B31: Officer compensation — reasonable comp analysis | C31: Payroll records / W-2s / ADP report | D31: W-2s for all officers (Principal Shareholder $95K, — $65K). Pg 1 Ln 7/8. Verify comp is "reasonable" — IRS scrutinizes S-corp officer comp heavily. | H31: Pg 1 Ln 7-8
A32: DOC-02 | B32: Payroll tax summary | C32: Form 941 (quarterly) / W-3 / state returns | D32: Annual W-3, quarterly 941s. Tie total wages to P&L. Verify payroll taxes match 941 filings. Also need for §199A W-2 wages (K-1 Box 17W). | H32: Pg 1 Ln 8 / K-1 Box 17W
A33: DOC-03 | B33: Vehicle use log / mileage records | C33: IRS mileage log or fleet tracking | D33: If claiming actual expenses, need business use %. If >50% business, MACRS allowed. If ≤50%, must use SL. Listed property rules apply. Form 4562 Part V. | H33: Form 4562 Part V
A34: DOC-04 | B34: Loan amortization schedule(s) | C34: Bank statements / amort schedules | D34: LOC and vehicle loan: beginning balance, payments, interest, ending balance. Verify interest expense on P&L ($8,200 LOC + $2,400 vehicle = $10,600 per PBC). | H34: Pg 1 Ln 13 / Sch L
A35: DOC-05 | B35: Prior-year tax return (complete) | C35: 1120-S + all schedules + K-1s | D35: CRITICAL: Need prior-year Sch L ending balances (→ this year BOY), prior-year 7203 ending basis, prior-year AAA/OAA balances. Without this, multiple tabs cannot be completed. | H35: Sch L BOY / M-2 BOY / 7203 Ln 1
A36: DOC-06 | B36: Fixed asset / depreciation schedule | C36: Tax depreciation software output | D36: Complete asset list with tax basis, MACRS method, convention, life, prior depr, current depr. Drives Form 4562 and Sch L fixed assets. Verify disposals. | H36: Form 4562 / Sch L Ln 10
A37: DOC-07 | B37: Distribution records | C37: Board minutes / bank records | D37: Dates and amounts of each distribution to each SH. Verify J ($180K) + S ($120K) = $300K total. Pro rata to ownership? If not, risk second class of stock issue. | H37: K Ln 16d / M-2 / 7203
A38: DOC-08 | B38: Shareholder loan documentation | C38: Promissory note / repayment records | D38: Principal Shareholder $25K loan: note terms, interest rate, repayment schedule. Is there economic substance? Bona fide debt for 7203 debt basis? Below-market interest → §7872 imputed interest. | H38: 7203 Part II / Sch L Ln 19
A39: DOC-09 | B39: Entity-level state returns / estimates | C39: State return info / estimate payments | D39: Some states have entity-level taxes (e.g., CA $800 min franchise tax, PTE elections). Get state filing requirements and any estimated tax payments. | H39: State returns
A40: DOC-10 | B40: §199A qualified business income info | C40: QBI worksheets | D40: For each SH: QBI (usually = OBI), W-2 wages, UBIA of qualified property. SH takes 20% deduction on personal return. Need to report on K-1 Box 17 codes V/W/X. | H40: K-1 Box 17V/W/X
B42: CHECKSUM — AJE NET EFFECT PROOF
B43: Total DR (all AJEs) | E43: =SUM(E8:E28)
...

Sheet Schedule K
A1: [ENTITY NAME] — Schedule K — Shareholders' Pro Rata Share Items
A2: Tax Year Ended [MM/DD/YYYY]
A3: [ENTITY NAME] (S-Corp) — EIN: [XX-XXXXXXX]
A5: SHAREHOLDER OWNERSHIP
A6: Shareholder | B6: Principal Shareholder (100%) | C6: — (N/A)
A7: [SH1 Name] — Ownership % | B7: 1 | C7: 0
A9: K Line | B9: Description | C9: WTB Row / Source | D9: Amount | E9: K-1 Box | F9: Principal Shareholder (100%) | G9: — (N/A) | H9: Notes / Typical Items
B10: INCOME (LOSS)
A11: 1 | B11: Ordinary business income (loss) | C11: WTB r136, Col D | D11: ='Working Trial Balance'!F155 | E11: Box 1 | F11: =D11*B7 | G11: =D11*C7 | H11: Pg 1, Ln 21 → K Ln 1. Same amount.
A12: 2 | B12: Net rental real estate income (loss) | C12: Form 8825 | E12: Box 2 | H12: ⚠ MANUALLY ENTER — From Form 8825 if applicable
A13: 3a | B13: Net rental income — other (gross income) | C13: WTB r66 (−C66) | D13: =-'Working Trial Balance'!C66 | E13: Box 3 | F13: =D13*B7 | G13: =D13*C7 | H13: Rental income moved from Pg 1 to K. Desert Peak: $85K equipment rental.
A14: 3b | B14: Net rental income — other (expenses) | C14: WTB r121 | D14: ='Working Trial Balance'!D121*-1 | E14: Box 3 | F14: =D14*B7 | G14: =D14*C7 | H14: Rental expenses. Desert Peak: $35K equipment rental expense.
A15: 3c | B15: Net rental income — other (net) | C15: Ln 3a + Ln 3b | D15: =D13+D14 | E15: Box 3 | F15: =D15*B7 | G15: =D15*C7 | H15: Net = income − expenses. Should tie to M-2 AAA rental line.
A16: 4 | B16: Interest income | C16: WTB r68 (−C68) | D16: ='Working Trial Balance'!F133 | E16: Box 4 | F16: =D16*B7 | G16: =D16*C7 | H16: Bank interest, etc. Removed from Pg 1, separately stated on K.
A17: 5a | B17: Ordinary dividends | C17: WTB r69 (−C69) | E17: Box 5a | F17: =D17*B7 | G17: =D17*C7 | H17: All dividends. Qualified portion goes to 5b.
A18: 5b | B18: Qualified dividends | C18: PBC / 1099-DIV | E18: Box 5b | F18: =D18*B7 | G18: =D18*C7 | H18: ⚠ MANUALLY ENTER — Verify against 1099-DIV. Must be ≤ Line 5a.
A19: 6 | B19: Royalties | E19: Box 6 | H19: Oil/gas, intellectual property, etc.
A20: 7 | B20: Net short-term capital gain (loss) | C20: Form 8949 / Sch D | D20: ='Working Trial Balance'!F135 | E20: Box 7 | H20: From Sch D. Holding period ≤ 1 year.
A21: 8a | B21: Net long-term capital gain (loss) | C21: WTB r70 (−C70) | D21: =-'Working Trial Balance'!C70 | E21: Box 8a | F21: =D21*B7 | G21: =D21*C7 | H21: From Sch D. Desert Peak: $12K LTCG from stock sales.
A22: 8b | B22: Collectibles (28%) gain (loss) | E22: Box 8b | H22: Art, antiques, precious metals, etc.
A23: 8c | B23: Unrecaptured §1250 gain | E23: Box 8c | H23: Gain on sale of depreciable real property. From Form 4797.
A24: 9 | B24: Net §1231 gain (loss) | C24: WTB r71 (−C71) | D24: =-'Working Trial Balance'!C71 | E24: Box 9 | F24: =D24*B7 | G24: =D24*C7 | H24: From Form 4797. Desert Peak: $5K §1231 portion of equipment sale.
A25: 10 | B25: Other income (loss) | E25: Box 10 | H25: Cancellation of debt, gambling, etc. Attach statement.
B26: DEDUCTIONS
A27: 11 | B27: §179 deduction | C27: WTB r110 | D27: ='Working Trial Balance'!D110 | E27: Box 11 | F27: =D27*B7 | G27: =D27*C7 | H27: From Form 4562. Desert Peak: $17K. Subject to business income limitation.
A28: 12a | B28: Charitable contributions | C28: WTB r114 (F col) | D28: ='Working Trial Balance'!F114 | E28: Box 12A | F28: =D28*B7 | G28: =D28*C7 | H28: Cash + noncash. 50%/30%/20% AGI limits apply at SH level. Desert Peak: $15K.
A29: 12b | B29: Investment interest expense | E29: Box 12H | H29: Form 4952 at SH level. Margin interest, etc.
A30: 12c(1) | B30: Net §59(e)(2) expenditures — Type | E30: Box 12I/J | H30: Intangible drilling, mining, research — SH can elect to amortize.
A31: 12c(2) | B31: Net §59(e)(2) expenditures — Amount | E31: Box 12I/J
A32: 12d | B32: Other deductions | E32: Box 12 | H32: Attach statement. Soil/water conservation, etc.
A33: 13a | B33: Low-income housing credit (§42(j)(5)) | E33: Box 13A
A34: 13b | B34: Low-income housing credit (other) | E34: Box 13B
A35: 13c | B35: Qualified rehabilitation expenditures | E35: Box 13C
A36: 13d | B36: Other rental real estate credits | E36: Box 13D
A37: 13e | B37: Other rental credits | E37: Box 13E
A38: 13f | B38: Biofuel producer credit | E38: Box 13F
A39: 13g | B39: Other credits | E39: Box 13G | H39: R&D credit (Form 6765), W.O.T.C., etc. Attach statement.
B40: FOREIGN TRANSACTIONS
A41: 14a | B41: Name of country or U.S. possession | E41: Box 14 | H41: If foreign income/taxes paid
A42: 14b | B42: Gross income — general category | E42: Box 14
...

Sheet Schedule M-1
A1: [ENTITY NAME] — Schedule M-1 — Reconciliation of Income (Loss) per Books With Income (Loss) per Return
A2: Tax Year Ended [MM/DD/YYYY]
A3: [ENTITY NAME] (S-Corp) — EIN: [XX-XXXXXXX]
A4: M-1 reconciles book net income → income per return. If gross receipts > $250K AND total assets > $10M at year-end, use Schedule M-3 instead.
A6: M-1 Line | B6: Description | C6: WTB Row / Source | D6: Amount | E6: Typical Items (Highlight = common for most clients) | F6: Ties To | G6: Notes
A7: 1 | B7: Net income (loss) per books | C7: WTB r139 / PBC P&L | D7: ='P&L'!B63 | E7: ALWAYS: Net income from financial statements / QuickBooks / PBC P&L. This is BOOK income, not tax. | F7: PBC P&L bottom line | G7: Must match P&L exactly. If client provides adjusted TB, may need to reconcile.
A8: 2 | B8: Income included on Sch K not on books | E8: RARE for S-corps. Example: income recognized on return earlier than books (installment sale reversal). Most clients = $0. | F8: Sch K detail | G8: Leave blank unless you have a specific item.
B9: LINE 3: EXPENSES ON BOOKS NOT DEDUCTED ON RETURN (ADD BACKS)
A10: 3a | B10: Book depreciation (replaced by tax MACRS) | C10: WTB r105-108 | D10: ='Working Trial Balance'!D105+'Working Trial Balance'!D106+'Working Trial Balance'!D107+'Working Trial Balance'!D108 | E10: COMMON: Book SL depreciation. Added back because tax uses MACRS (Ln 6a). Desert Peak: $60K book depr. | F10: Form 4562 | G10: Must tie to book depreciation schedule / fixed asset report. | H10: Placeholder till I get UT to work
A11: 3b | B11: >2% Shareholder health insurance | C11: WTB r91 (F col) | D11: ='Working Trial Balance'!D91 | E11: COMMON: Officer health insurance for >2% shareholders. Not deducted on 1120-S — goes on officer W-2 Box 1 and K-1. | F11: W-2 / K-1 | G11: Deducted on SH personal return (pg 1, line 17 of 1040). NOT on 1120-S.
A12: 3c | B12: Meals — 50% disallowance | C12: WTB r99 (F col) | D12: ='Working Trial Balance'!H99 | E12: COMMON: 50% of business meals (post-2022). $18K total × 50% = $9K disallowed. 50% IS on Pg 1. | F12: Pg 1, Ln 19 | G12: Verify: some years had 100% deduction (2021-2022 restaurant meals).
A13: 3d | B13: Entertainment (100% disallowed) | C13: WTB r100 (F col) | D13: ='Working Trial Balance'!H100 | E13: COMMON: All entertainment is 100% nondeductible post-TCJA. Sporting events, golf, concerts, etc. | F13: N/A ($0 on return) | G13: Confirm client properly separates meals from entertainment in their books.
A14: 3e | B14: Charitable contributions (separately stated) | C14: WTB r114 (F col) | D14: ='Working Trial Balance'!D114 | E14: COMMON: Deducted on books but separately stated on K Ln 12a. SH deducts on personal Sch A. | F14: K Ln 12a | G14: If corp received property donations, may need Form 8283 at SH level.
A15: 3f | B15: Political contributions | C15: WTB r115 (F col) | D15: ='Working Trial Balance'!D115 | E15: COMMON: 100% nondeductible. Lobbying, political campaigns, PACs. | F15: K Ln 16c | G15: Reduces SH basis only. Does NOT reduce AAA.
A16: 3g | B16: Penalties & fines | C16: WTB r116 (F col) | D16: ='Working Trial Balance'!D116 | E16: COMMON: Late filing penalties, parking tickets, regulatory fines. 100% nondeductible. | F16: K Ln 16c | G16: Exception: some restitution payments may be deductible — check §162(f).
A17: 3h | B17: Life insurance premiums (corp beneficiary) | C17: WTB r117 (F col) | D17: ='Working Trial Balance'!D117 | E17: COMMON: Key person life insurance where corp is beneficiary. Nondeductible. | F17: K Ln 16c | G17: If SH is beneficiary, may be compensation. Different treatment.
A18: 3i | B18: Club dues | C18: WTB r118 (F col) | D18: ='Working Trial Balance'!D118 | E18: COMMON: Country club, social club, athletic club. 100% nondeductible since 1993. | F18: K Ln 16c | G18: Business meals AT a club ARE deductible (50%) — separate those out.
A19: 3j | B19: Officers' life insurance (excess) | D19: ='Working Trial Balance'!H113 | E19: If >$50K term life provided to officers. Excess over $50K is nondeductible and included in W-2. | F19: W-2
A20: 3k | B20: Excess compensation (reasonable comp issue) | E20: RARE: If IRS determines officer comp exceeds reasonable amount. Amount reclassified as distribution. | G20: Typically only on exam / audit. Leave blank unless specific issue.
A21: 3l | B21: Travel & entertainment (other disallowed) | E21: Luxury water transportation, first-class airfare limits (usually immaterial). Check for "lavish or extravagant" items.
A22: 3m | B22: Other expenses on books not on return | E22: Catch-all: reserves, accrued expenses not deductible until paid (§461(h)), warranty accruals, etc. | G22: Attach detail if material. Consider if timing (temporary) or permanent.
A23: 3 | B23: TOTAL LINE 3 — Expenses on books not on return | C23: WTB r150 | D23: =SUM(D10:D22) | F23: WTB M-1 Ln 3 total
A24: 4 | B24: TOTAL (Lines 1 + 2 + 3) | D24: =D7+D8+D23 | G24: This is book NI adjusted for all items deducted on books but not on return.
B25: LINE 5: INCOME INCLUDED ON BOOKS NOT ON RETURN (SUBTRACT)
A26: 5a | B26: Tax-exempt interest income | C26: WTB r72 (F col) | D26: 0 | E26: COMMON: Municipal bond interest. On books as income but NOT taxable. Remove for tax. | F26: K Ln 16a | G26: Goes to OAA on M-2, not AAA. Sign should be negative (subtracting from Ln 4).
A27: 5b | B27: Unrealized gains/losses | C27: WTB r73 (F col) | D27: =-'Working Trial Balance'!D136 | E27: COMMON: Mark-to-market gains/losses on investments. Book income, not realized for tax. | F27: N/A (not on return) | G27: GAAP requires recognition; tax waits until sale. Reverse when sold.
A28: 5c | B28: Life insurance proceeds | E28: If corp received death benefit on key person policy. Book income, not taxable (§101). | F28: K Ln 16b | G28: Goes to OAA.
A29: 5d | B29: PPP loan forgiveness | E29: Was common 2020-2022. Book income from forgiveness, excluded from taxable income. | F29: K Ln 16b | G29: Related expenses ARE still deductible (Rev Proc 2021-48).
A30: 5e | B30: Other income on books not on return | E30: Installment sale income deferred for tax, income from flow-through entities recognized differently, etc.
A31: 5 | B31: TOTAL LINE 5 — Income on books not on return | C31: WTB r155 | D31: =SUM(D26:D30) | F31: WTB M-1 Ln 5 total | G31: These amounts should be NEGATIVE (reducing income per return). F column in WTB carries sign.
B32: LINE 6: DEDUCTIONS ON RETURN NOT ON BOOKS (SUBTRACT)
A33: 6a | B33: Tax depreciation — MACRS / bonus | C33: WTB r109 (F col) | D33: =-'Working Trial Balance'!F109 | E33: COMMON: Tax MACRS/bonus depreciation replaces book SL. Usually LARGER than book depr → negative here. | F33: Form 4562 / Pg 1 Ln 14 | G33: Desert Peak: $75K MACRS. Compare to $60K book depr (Ln 3a). Net extra deduction = $15K.
A34: 6b | B34: §179 deduction | C34: WTB r110 (F col) | D34: =-'Working Trial Balance'!F110 | E34: COMMON: Immediate expensing of qualifying assets. $1,220,000 limit (2024). Separately stated on K Ln 11. | F34: K Ln 11 / Form 4562 | G34: Desert Peak: $17K. Subject to business income limitation and total asset phase-out.
A35: 6c | B35: Bonus depreciation (if separate from MACRS) | E35: 100% bonus expired after 2022. 80% for 2023, 100% for 2024, 0% for 2025, 20% for 2026. Often combined with 6a. | F35: Form 4562 | G35: If your depreciation software breaks out bonus separately, add here. Otherwise included in 6a.
A36: 6d | B36: Amortization (tax vs book difference) | E36: §197 intangibles, organizational costs, start-up costs. Tax amortization may differ from book. | F36: Form 4562 Part VI
A37: 6e | B37: Other deductions on return not on books | E37: Catch-all: depletion, soil/water conservation, exploration expenditures, etc.
A38: 6 | B38: TOTAL LINE 6 — Deductions on return not on books | C38: WTB r159 | D38: =SUM(D33:D37) | F38: WTB M-1 Ln 6 total | G38: These amounts should be NEGATIVE (they reduce income per return).
A40: 7 | B40: INCOME (LOSS) PER RETURN (Line 4 + Line 5 + Line 6) | D40: =D24+D31+D38 | G40: THIS IS THE KEY NUMBER. Should = sum of all Sch K income items. Ties to WTB M-1 proof.
A42: TIE-OUT CHECKS
B43: M-1 Line 7 = WTB M-1 Proof Line 7 | D43: =D40-'Working Trial Balance'!H180 | E43: =IF(D43=0,"✓ TIES","✗ OFF")
...

Sheet Schedule M-2
A1: [ENTITY NAME] — Schedule M-2 — Analysis of AAA, OAA, and Shareholders' Equity
A2: Tax Year Ended [MM/DD/YYYY]
A3: M-2 is TAX BASIS. PBC Balance Sheet is BOOK BASIS. The equity tie-out at the bottom reconciles the difference.
B5: AAA (Accumulated Adjustments Account) | C5: OAA (Other Adjustments Account) | D5: PTI (Previously Taxed Income) | E5: Retained Earnings (per Books) | F5: Sch K Line / Source | G5: Notes
A6: 1. Balance at beginning of tax year | F6: Prior-year M-2 / Sch L | G6: ⚠ MANUALLY ENTER: Must tie to prior-year M-2 ending balances. Obtain from prior-year return.
A8: INCREASES
A9: 2. Ordinary business income (loss) | B9: ='Working Trial Balance'!F155 | E9: ='PBC - P&L2'!B63 | F9: K Ln 1 / Pg 1 Ln 21 | G9: AAA = tax OBI from WTB. RE = book net income from P&L.
A10: 3a. Net rental income (equipment) | B10: =-('Working Trial Balance'!C66)-'Working Trial Balance'!D121 | F10: K Ln 3a | G10: Net rental = income (−C66 = $85K moved to K) minus expenses (D121 = $35K). K Ln 3a net = $50K.
A11: 3b. Interest income | B11: ='Schedule K'!D16 | F11: K Ln 4 | G11: Sch K adj was negative (removed from Pg 1). Flip sign for AAA increase.
A12: 3c. Dividend income | B12: ='Schedule K'!D17 | F12: K Ln 5a | G12: Same — flip Sch K adj sign. Qualified $6,800 → K Ln 5b.
A13: 3d. Net capital gains | B13: ='Schedule K'!D20 | F13: K Ln 8a | G13: Net LTCG from stock sales = $12K. §1245 recapture ($10K) is ordinary income already in OBI (Ln 2). Only net capital gain goes here.
A14: 3e. §1231 gain (net) | F14: K Ln 9 | G14: §1231 portion of equipment sale gain → AAA
A15: 3f. Ordinary gain (§1245 recapture) | B15: 0 | F15: Pg 1 Ln 4 / F.4797 | G15: §1245 recapture ($10K) is ORDINARY income → Pg 1 Ln 4 → Ln 21 → already in OBI (Ln 2 above). DO NOT add here — would double count.
A16: 3g. Tax-exempt interest | C16: ='Working Trial Balance'!C72*-1 | F16: K Ln 16a | G16: Tax-exempt income → OAA, NOT AAA. Increases SH basis.
A17: 3h. Other tax-exempt income | F17: K Ln 16b | G17: PPP forgiveness, life insurance proceeds → OAA if applicable.
A18: Total Increases | B18: =SUM(B9:B17) | C18: =SUM(C9:C17) | D18: =SUM(D9:D17) | E18: =SUM(E9:E17)
A20: DECREASES
A21: 4a. Ordinary business loss | F21: K Ln 1 | G21: If loss year — decreases AAA (can go negative from losses)
A22: 4b. §179 deduction | B22: 0 | F22: See note → | G22: ⚠ §179 ($17K) is included in D column deductions (WTB row 110), which reduces OBI in Ln 2 above. Listing it here would DOUBLE-COUNT. Set to $0. If your WTB moves §179 out of the D column, add it back here.
A23: 4c. Charitable contributions | B23: ='Schedule K'!D28 | F23: K Ln 12a | G23: Separately stated → decreases AAA. Uses M-1 col (F) because that's where the separately stated amount is.
A24: 4d. Nondeductible expenses (K Ln 16c) | B24: ='Schedule K'!D58 | F24: K Ln 16c | G24: These reduce SH BASIS only. They do NOT reduce AAA. Total $42,700 → K-1 Box 16C.
A25: • 50% meals disallowance $___ | G25: Basis only
A26: • Entertainment (100%) $___ | G26: Basis only
A27: • Penalties & fines $___ | G27: Basis only
A28: • Political contributions $___ | G28: Basis only
A29: • Life insurance (corp beneficiary) $___ | G29: Basis only
A30: • Club dues $___ | G30: Basis only
A31: Total nondeductible $___ | F31: K Ln 16c | G31: Reduces SH basis. Does NOT reduce AAA.
A32: Total Decreases | B32: =SUM(B21:B24) | C32: =SUM(C21:C24) | D32: =SUM(D21:D24) | E32: =SUM(E21:E24)
A34: 5. Distributions | B34: =-' Balance Sheet'!E62 | E34: =B34 | F34: K Ln 16d | G34: Principal Shareholder $180K + — $120K = $300K. Formulas pull from WTB.
A35: DISTRIBUTION ORDERING RULES:
A36: 1st: Reduce AAA (cannot go negative from distributions) | G36: Excess → next bucket
A37: 2nd: Reduce accumulated E&P (taxed as DIVIDEND to SH) | G37: Only if prior C-corp — N/A here
A38: 3rd: Reduce OAA | G38: Tax-free to extent of OAA
A39: 4th: Return of capital (reduce stock basis) | G39: Tax-free to extent of basis
A40: 5th: Capital gain | G40: Excess over all basis → taxable LTCG
A42: 6. ENDING BALANCE | B42: =B6+B18-B32-B34 | C42: =C6+C18-C32 | D42: =D6+D18-D32 | E42: =E6+E18-E32-E34 | G42: See equity tie-out below.
A44: CHECK 1: AAA CANNOT GO NEGATIVE FROM DISTRIBUTIONS
A45: AAA before distributions | B45: =B6+B18-B32
A46: Distributions | B46: =B34
...

Sheet Schedule L
A1: [ENTITY NAME] — Schedule L — Balance Sheets per Books
A2: Tax Year Ended [MM/DD/YYYY]
A3: [ENTITY NAME] (S-Corp) — EIN: [XX-XXXXXXX]
A4: BOY = Beginning of Year (from prior-year return Sch L ending balances). EOY = End of Year (from current-year PBC / WTB). Red cells = manually enter from prior-year return.
A6: Line | B6: Description | C6: [PY] Amount | D6: (b) BOY Amount | E6: [CY] Amount | F6: (d) EOY Amount | G6: Ties To | H6: Notes / Source
B7: Sch L has dual columns: (a)/(c) for gross amounts, (b)/(d) for offsets (e.g., reserves, accum depr). Some lines use only (b)/(d).
B8: ASSETS
A9: 1 | B9: Cash | E9: =' Balance Sheet'!B8 | G9: WTB r8-9 | H9: ⚠ MANUALLY ENTER — BOY from prior-year 1120-S, Sch L Ln 1(d)
A10: 2a | B10: Trade notes & accounts receivable | E10: =' Balance Sheet'!B10 | G10: WTB r10 | H10: ⚠ MANUALLY ENTER — BOY from prior-year Sch L Ln 2a(a)
A11: 2b | B11: Less allowance for bad debts | E11: ='Working Trial Balance'!F11 | G11: WTB r11 | H11: ⚠ MANUALLY ENTER — BOY from prior-year Sch L Ln 2b(b)
A12: 3 | B12: Inventories | E12: =' Balance Sheet'!B14 | G12: WTB r14 | H12: ⚠ MANUALLY ENTER — BOY from prior-year Sch L Ln 3(d)
A13: 4 | B13: U.S. government obligations | H13: Treasury bills, notes, bonds. Most S-corps leave blank.
A14: 5a | B14: Tax-exempt securities | E14: =' Balance Sheet'!B19 | G14: WTB r18 | H14: ⚠ MANUALLY ENTER — BOY from prior-year Sch L Ln 5a(d)
A15: 6 | B15: Other current assets | E15: =' Balance Sheet'!B12+' Balance Sheet'!B13 | G15: WTB r12-13 | H15: ⚠ MANUALLY ENTER — BOY from prior-year Sch L Ln 6(d)
A16: 7 | B16: Loans to shareholders
A17: 8 | B17: Mortgage & real estate loans | H17: Notes receivable from RE loans. Most service S-corps = $0.
A18: 9 | B18: Other investments | E18: =' Balance Sheet'!B18 | G18: WTB r17 | H18: ⚠ MANUALLY ENTER — BOY from prior-year Sch L Ln 9(d)
A19: 10a | B19: Buildings & other depreciable assets | E19: =' Balance Sheet'!B23+' Balance Sheet'!B25+' Balance Sheet'!B27+' Balance Sheet'!B29 | G19: WTB r21,23,25,27 | H19: ⚠ MANUALLY ENTER — BOY from prior-year Sch L Ln 10a(a). If tax-basis Sch L, use tax cost basis.
A20: 10b | B20: Less accumulated depreciation | E20: =' Balance Sheet'!B24+' Balance Sheet'!B26+' Balance Sheet'!B28+' Balance Sheet'!B30 | G20: WTB r22,24,26,28 | H20: ⚠ MANUALLY ENTER — BOY from prior-year Sch L Ln 10b(b). CRITICAL: book vs tax depr difference.
A21: 11a | B21: Depletable assets | H21: Oil/gas, mining, timber. Most service S-corps = $0.
A22: 11b | B22: Less accumulated depletion
A23: 12 | B23: Land (net of any amortization) | H23: Land is NOT depreciable. Separate from Ln 10a.
A24: 13a | B24: Intangible assets (amortizable only) | E24: =' Balance Sheet'!B35 | G24: WTB r32 | H24: ⚠ MANUALLY ENTER — BOY from prior-year Sch L Ln 13a(a)
A25: 13b | B25: Less accumulated amortization | H25: If PBC provides org costs NET, this may be $0 and net amount goes in 13a. Check.
A26: 14 | B26: Other assets (attach statement) | E26: =' Balance Sheet'!B34 | G26: WTB r31 | H26: ⚠ MANUALLY ENTER — BOY from prior-year Sch L Ln 14(d)
A27: 15 | B27: TOTAL ASSETS | C27: =SUM(C9:C26) | D27: =D11+D20 | E27: =SUM(E9:E26) | F27: =F11+F20 | G27: WTB r35 | H27: Net total assets = (a/c) gross − (b/d) contras. Must tie to WTB Total Assets.
E28: =E27-'Working Trial Balance'!F35
B29: LIABILITIES AND SHAREHOLDERS' EQUITY
A30: 16 | B30: Accounts payable | F30: =' Balance Sheet'!B42 | G30: WTB r38 | H30: ⚠ MANUALLY ENTER — BOY from prior-year Sch L Ln 16(d)
A31: 17 | B31: Mortgages, notes, bonds payable < 1 year | F31: =' Balance Sheet'!B47 | G31: WTB r43 | H31: ⚠ MANUALLY ENTER — BOY from prior-year Sch L Ln 17(d)
A32: 18 | B32: Other current liabilities (attach statement) | F32: =' Balance Sheet'!B43+' Balance Sheet'!B44+' Balance Sheet'!B45+' Balance Sheet'!B46 | G32: WTB r39-42 | H32: ⚠ MANUALLY ENTER — BOY from prior-year Sch L Ln 18(d)
A33: 19 | B33: Loans from shareholders | F33: =' Balance Sheet'!B53 | G33: WTB r46 | H33: ⚠ MANUALLY ENTER — BOY from prior-year Sch L Ln 19(d)
A34: 20 | B34: Mortgages, notes, bonds payable ≥ 1 year | F34: =' Balance Sheet'!B51+' Balance Sheet'!B52 | G34: WTB r44-45 | H34: ⚠ MANUALLY ENTER — BOY from prior-year Sch L Ln 20(d)
A35: 21 | B35: Other liabilities (attach statement) | F35: ='Working Trial Balance'!F44 | H35: Deferred revenue, deferred rent, contingent liabilities. Desert Peak: none.
A36: 22a | B36: Capital stock | F36: =' Balance Sheet'!B59 | G36: WTB r50 | H36: ⚠ MANUALLY ENTER — BOY from prior-year Sch L Ln 22a(d)
A37: 23 | B37: Additional paid-in capital | F37: =' Balance Sheet'!B60 | G37: WTB r51 | H37: ⚠ MANUALLY ENTER — BOY from prior-year Sch L Ln 23(d)
A38: 24 | B38: Retained earnings | F38: =' Balance Sheet'!B65-' Balance Sheet'!B59-' Balance Sheet'!B60 | G38: WTB r52-55 / M-2 | H38: ⚠ MANUALLY ENTER — BOY from prior-year Sch L Ln 24(d). CRITICAL: This is BOOK RE, not AAA.
A39: 25 | B39: Adjustments to shareholders' equity (attach statement) | H39: Unrealized gains/losses on AFS securities (OCI), foreign currency adjustments. Most S-corps = $0.
A40: 26 | B40: Less cost of treasury stock | H40: S-corps can only have one class of stock. Treasury stock is rare. Leave blank unless repurchased shares.
A41: 27 | B41: TOTAL LIABILITIES & SHAREHOLDERS' EQUITY | D41: =SUM(D30:D38) | F41: =SUM(F30:F40) | G41: WTB r58 | H41: Must = Total Assets (Ln 15). If off, check each section.
...

Sheet 7203 - Principal SH
A1: [ENTITY NAME] — Form 7203 — S Corporation Shareholder Stock and Debt Basis Limitations
A2: Tax Year Ended [MM/DD/YYYY]
A3: Shareholder: [NAME]
A4: Filed with shareholder's Form 1040. Required if SH claims loss/deduction, receives distribution, disposes of stock, or receives loan repayment.
A6: Line | B6: Description | C6: K-1 Box / Source | D6: Amount | E6: Running Basis | F6: Ties To | G6: Notes
B7: PART I — SHAREHOLDER STOCK BASIS
A8: 1 | B8: Stock basis at beginning of corporation's tax year | C8: Prior-year 7203 Ln 27 | G8: ⚠ MANUALLY ENTER — Beginning stock basis from prior-year Form 7203 Line 27 (or initial cost basis if first year). This is the MOST CRITICAL input.
A9: 2 | B9: Stock purchased or additional capital contributions during year | C9: Stock certs / PBC | D9: 0 | G9: ⚠ MANUALLY ENTER — Only if new capital contributed this year. Usually $0.
A10: 3 | B10: Basis from restored debt repayment (from Part II, if applicable) | C10: Part II below | D10: 0 | G10: Only if SH had reduced debt basis in prior year AND corp repaid some debt this year. Rare.
B11: INCREASES TO STOCK BASIS
A12: 4 | B12: Ordinary business income (K-1 Box 1) | C12: K-1 Box 1 / Sch K Ln 1 | D12: ='Schedule K'!F11 | F12: Sch K Ln 1 | G12: Pro rata share of OBI. Increases basis even though SH may not receive cash.
A13: 5 | B13: Net rental income (K-1 Box 2/3) | C13: K-1 Box 3 / Sch K Ln 3c | D13: 0 | F13: Sch K Ln 3c | G13: Net rental income (if positive). If negative, goes to loss section below.
A14: 6 | B14: Interest + dividends + capital gains + §1231 gains (K-1 Boxes 4-9) | C14: K-1 Boxes 4,5a,8a,9 | D14: ='Schedule K'!F16+'Schedule K'!F17+'Schedule K'!F21+'Schedule K'!F24 | F14: Sch K Ln 4+5a+8a+9 | G14: All separately stated income items: interest, dividends, LTCG, §1231. Only include positive amounts here.
A15: 7 | B15: Tax-exempt income (K-1 Box 16A/16B) | C15: K-1 Box 16A / Sch K Ln 16a | D15: 0 | F15: Sch K Ln 16a | G15: Muni bond interest. INCREASES basis even though not taxable. This is why it goes to OAA, not AAA.
A16: 8 | B16: Excess depletion (oil & gas) | C16: K-1 Box 15D | D16: 0 | G16: Only for oil/gas. Most S-corps = $0.
A17: 9 | B17: TOTAL INCREASES (Lines 4 through 8) | D17: =SUM(D12:D16) | G17: Sum of all items that increase SH stock basis.
A18: 10 | B18: Stock basis before distributions & losses (Ln 1 + 2 + 3 + 9) | D18: =D8+D9+D10+D17 | E18: =D18 | G18: KEY CHECKPOINT: This is your basis before subtracting distributions. Distributions cannot reduce basis below zero.
B19: DISTRIBUTIONS & NON-DIVIDEND DISTRIBUTIONS
A20: 11 | B20: Distributions (excluding dividend distributions) (K-1 Box 16D) | C20: K-1 Box 16D / Sch K Ln 16d | D20: ='Schedule K'!F59 | F20: Sch K Ln 16d / M-2 | G20: This SH's share of total distributions. Cannot reduce stock basis below zero — excess = capital gain.
A21: 12 | B21: Stock basis after distributions (Ln 10 − Ln 11, but not below zero) | D21: =MAX(D18-D20,0) | E21: =D21 | G21: If distributions > Ln 10, excess is capital gain to SH (report on Sch D). Basis cannot go negative from distributions.
B22: ► Distribution excess (capital gain to SH) | D22: =MAX(D20-D18,0) | E22: =IF(D22>0,"⚠ CG to SH","OK - within basis") | G22: If > 0, shareholder must report this as capital gain on personal Sch D. Basis drops to $0.
B23: DECREASES TO STOCK BASIS (order matters per §1367)
A24: 13 | B24: Nondeductible, noncapital expenses (K-1 Box 16C) | C24: K-1 Box 16C / Sch K Ln 16c | D24: ='Schedule K'!F58 | F24: Sch K Ln 16c | G24: Meals 50%, entertainment, political, penalties, life ins, club dues, >2% SH health. Reduces basis but NOT deductible.
A25: 14 | B25: Deductions — §179 expense (K-1 Box 11) | C25: K-1 Box 11 / Sch K Ln 11 | D25: 0 | F25: Sch K Ln 11 | G25: §179 expensing. Limited by SH basis AND SH business income. Already included in OBI for AAA but separately stated on K.
A26: 15 | B26: Deductions — Charitable contributions (K-1 Box 12A) | C26: K-1 Box 12A / Sch K Ln 12a | D26: ='Schedule K'!F28 | F26: Sch K Ln 12a | G26: Separately stated. SH deducts on personal Sch A. Still reduces stock basis regardless of SH AGI limits.
A27: 16 | B27: Other deductions, losses, and items that decrease basis | C27: K-1 various | D27: 0 | G27: Investment interest expense (Box 12H), net OBL if negative (Box 1), rental losses (Box 2/3), STCL (Box 7), other. Include any negative K-1 items here.
A28: 17 | B28: TOTAL DECREASES (Lines 13 through 16) | D28: =SUM(D24:D27) | G28: Total items that reduce stock basis. If this exceeds Ln 12, see Part III for loss limitations.
A29: 18 | B29: Allowable decrease (lesser of Ln 17 or Ln 12) | D29: =MIN(D28,D21) | G29: Cannot reduce stock basis below zero. Excess losses → carryforward (Part III) or to debt basis (Part II).
A30: 19 | B30: Suspended losses (Ln 17 − Ln 18, carried forward) | D30: =D28-D29 | E30: =IF(D30>0,"⚠ CARRYFORWARD","OK - all deducted") | G30: If > 0, these losses carry forward indefinitely until SH has sufficient basis. Track on next year's 7203.
A31: 20 | B31: STOCK BASIS AT END OF YEAR (Ln 12 − Ln 18) | D31: =D21-D29 | E31: =D31 | G31: THIS IS THE ENDING STOCK BASIS. Carries to next year's Ln 1. Should be ≥ $0. If $0, no further losses allowed against stock basis.
B33: PART II — SHAREHOLDER DEBT BASIS
B34: Debt basis = loans FROM the shareholder TO the corporation (not bank debt, not corp loans to SH). Only the SH who made the loan gets debt basis.
A35: 21 | B35: Shareholder debt basis at beginning of year | C35: Prior-year 7203 Ln 27 | G35: ⚠ MANUALLY ENTER — Debt basis from prior-year 7203. SH loan to corp = $25,000 per Sch L Ln 19. Debt basis may differ from loan balance if previously reduced.
A36: 22 | B36: Additional loans from SH to corp during year | C36: Loan docs / PBC | D36: 0 | G36: ⚠ MANUALLY ENTER — New loans from SH to corp this year. Verify with loan documents.
A37: 23 | B37: Debt basis before repayment and losses (Ln 21 + 22) | D37: =D35+D36 | G37: Available debt basis before any loan repayments or loss allocations.
A38: 24 | B38: Losses that exceeded stock basis, applied to debt basis | D38: =MIN(D30,D37) | G38: If stock basis hit $0 and there are excess losses, they reduce debt basis (up to debt basis amount). §1366(d)(1)(A).
A39: 25 | B39: Loan repayments from corporation to shareholder | C39: K-1 Box 16E / Loan docs | D39: 0 | G39: ⚠ MANUALLY ENTER — Loan repayments from corp to SH this year. Check bank records / loan amort schedule.
A40: 26 | B40: DEBT BASIS AT END OF YEAR (Ln 23 − 24 − 25) | D40: =MAX(D37-D38-D39,0) | E40: =D40 | G40: Ending debt basis. If reduced below face value of loan, a future repayment triggers gain recognition.
B41: ► Gain on loan repayment (if debt basis < repayment) | D41: =MAX(D39-D37+D38,0) | E41: =IF(D41>0,"⚠ TAXABLE GAIN","OK - no gain") | G41: If > 0, SH has ordinary income on loan repayment. Report on Form 1040. See §1367(b)(2).
B43: TOTAL BASIS SUMMARY
...

Sheet Schedule M-3
A1: [ENTITY NAME] — Schedule M-3 — Net Income (Loss) Reconciliation
A2: Tax Year Ended [MM/DD/YYYY]
A3: NOTE: Desert Peak files M-1 (assets < $10M). This M-3 is included as a template. All formulas tie to WTB.
A5: PART II — Reconciliation of Net Income per Income Statement to Income per Return
A6: Line Item | B6: (a) Book Amount | C6: (b) Temporary Differences | D6: (c) Permanent Differences | E6: (d) = a + b + c Tax Return Amount | F6: Ties To (Return Line) | G6: Notes
A7: INCOME ITEMS
A8: 1. Gross receipts / sales | B8: ='Working Trial Balance'!B64+'Working Trial Balance'!B65 | C8: 0 | D8: 0 | E8: =B8+C8+D8 | F8: Pg 1, Ln 1a | G8: Book consulting + software revenue from WTB
A9: 2. Returns & allowances | B9: ='Working Trial Balance'!B67 | C9: 0 | D9: 0 | E9: =B9+C9+D9 | F9: Pg 1, Ln 1b
A10: 3. Cost of goods sold | B10: =-'Working Trial Balance'!D80 | C10: 0 | D10: 0 | E10: =B10+C10+D10 | F10: Pg 1, Ln 2 | G10: Shown as negative (expense)
A11: 4. Interest income | B11: ='Working Trial Balance'!B68 | C11: 0 | D11: 0 | E11: =B11+C11+D11 | F11: K Ln 4 | G11: Portfolio — separately stated
A12: 5. Dividend income | B12: ='Working Trial Balance'!B69 | C12: 0 | D12: 0 | E12: =B12+C12+D12 | F12: K Ln 5a | G12: Qualified $6,800 → K Ln 5b
A13: 6. Capital gains (net LTCG) | B13: ='Working Trial Balance'!B70 | C13: 0 | D13: 0 | E13: =B13+C13+D13 | F13: K Ln 8a | G13: From Form 8949 / Sch D
A14: 7. Gain on sale of assets | B14: ='Working Trial Balance'!B71 | C14: 0 | D14: 0 | E14: =B14+C14+D14 | F14: Pg 1 Ln 4 / K Ln 9 | G14: Ordinary recapture $10K + §1231 $5K
A15: 8. Equipment rental income | B15: ='Working Trial Balance'!B66 | C15: 0 | D15: 0 | E15: =B15+C15+D15 | F15: K Ln 3a | G15: Separately stated rental activity
A16: 9. Tax-exempt interest | B16: ='Working Trial Balance'!B72 | C16: 0 | E16: =B16+C16+D16 | F16: K Ln 16a | G16: PERMANENT: Not taxable. Increases OAA & basis.
A17: 10. Unrealized gain on investments | B17: ='Working Trial Balance'!B73 | D17: 0 | E17: =B17+C17+D17 | F17: N/A | G17: TEMPORARY: Book mark-to-market not recognized for tax.
A18: TOTAL INCOME ITEMS | B18: =SUM(B8:B17) | C18: =SUM(C8:C17) | D18: =SUM(D8:D17) | E18: =SUM(E8:E17)
A20: EXPENSE / DEDUCTION ITEMS (shown as positive = expense)
A21: 11. Officer compensation | B21: ='Working Trial Balance'!B83+'Working Trial Balance'!B84 | C21: 0 | D21: 0 | E21: =B21+C21+D21 | F21: Pg 1, Ln 7 | G21: No book-tax diff. Verify reasonable comp.
A22: 12. Salaries & wages | B22: ='Working Trial Balance'!B88 | C22: 0 | D22: 0 | E22: =B22+C22+D22 | F22: Pg 1, Ln 8 | G22: Reconcile to W-3
A23: 13. Payroll taxes | B23: ='Working Trial Balance'!B89 | C23: 0 | D23: 0 | E23: =B23+C23+D23 | F23: Pg 1, Ln 12
A24: 14. >2% SH health insurance | B24: ='Working Trial Balance'!B91 | C24: 0 | E24: =B24+C24+D24 | F24: NOT on 1120-S | G24: PERMANENT: Added to W-2 instead. SH deducts on 1040.
A25: 15. Depreciation (book) | B25: 60000 | D25: 0 | E25: =B25+C25+D25 | F25: N/A — removed | G25: TEMPORARY: Book depr removed, replaced by tax MACRS.
A26: 16. Depreciation (tax MACRS/bonus) | B26: 0 | C26: ='Working Trial Balance'!D109 | D26: 0 | E26: =B26+C26+D26 | F26: Pg 1, Ln 14 | G26: TEMPORARY: Tax depr from Form 4562.
A27: 17. §179 deduction | B27: 0 | C27: ='Working Trial Balance'!D110 | D27: 0 | E27: =B27+C27+D27 | F27: K Ln 11 | G27: TEMPORARY: Separately stated. SH-level limit.
A28: 18. Business meals | B28: ='Working Trial Balance'!B99 | C28: 0 | E28: =B28+C28+D28 | F28: Pg 1 Ln 19 (50% only) | G28: PERMANENT: 50% disallowance.
A29: 19. Entertainment | B29: ='Working Trial Balance'!B100 | C29: 0 | E29: =B29+C29+D29 | F29: N/A — $0 | G29: PERMANENT: 100% nondeductible §274(a).
A30: 20. Charitable contributions | B30: ='Working Trial Balance'!B114 | C30: 0 | E30: =B30+C30+D30 | F30: K Ln 12a | G30: PERMANENT (entity): Separately stated. SH AGI limits.
A31: 21. Fines and penalties | B31: ='Working Trial Balance'!B116 | C31: 0 | E31: =B31+C31+D31 | F31: N/A — $0 | G31: PERMANENT: 100% nondeductible §162(f).
A32: 22. Political contributions | B32: ='Working Trial Balance'!B115 | C32: 0 | E32: =B32+C32+D32 | F32: N/A — $0 | G32: PERMANENT: 100% nondeductible.
A33: 23. Life insurance (corp beneficiary) | B33: ='Working Trial Balance'!B117 | C33: 0 | E33: =B33+C33+D33 | F33: N/A — $0 | G33: PERMANENT: Nondeductible — corp is beneficiary.
A34: 24. Club dues | B34: ='Working Trial Balance'!B118 | C34: 0 | E34: =B34+C34+D34 | F34: N/A — $0 | G34: PERMANENT: 100% nondeductible §274(a)(3).
A35: 25. Rent expense | B35: ='Working Trial Balance'!B93 | C35: 0 | D35: 0 | E35: =B35+C35+D35 | F35: Pg 1, Ln 11
A36: 26. Interest expense | B36: =-'Working Trial Balance'!B119-'Working Trial Balance'!B120 | C36: 0 | D36: 0 | E36: =B36+C36+D36 | F36: Pg 1, Ln 13 | G36: LOC + vehicle loan. Check §163(j).
A37: 27. Employee benefits + 401(k) | B37: ='Working Trial Balance'!B90+'Working Trial Balance'!B92 | C37: 0 | D37: 0 | E37: =B37+C37+D37 | F37: Pg 1, Ln 17-18 | G37: Staff health + 401(k)
A38: 28. Rental activity expenses | B38: 0 | C38: ='Working Trial Balance'!D121 | D38: 0 | E38: =B38+C38+D38 | F38: K Ln 3c | G38: Equipment rental expenses — separately stated
A39: 29. All other deductions | B39: ='Working Trial Balance'!B101+'Working Trial Balance'!B102+'Working Trial Balance'!B103+'Working Trial Balance'!B104+'Working Trial Balance'!B94+'Working Trial Balance'!B95+'Working Trial Balance'!B96+'Working Trial Balance'!B97+'Working Trial Balance'!B98+'Working Trial Balance'!B111+'Working Trial Balance'!B112+'Working Trial Balance'!B113 | C39: 0 | D39: 0 | E39: =B39+C39+D39 | F39: Pg 1, Ln 9/16/19 | G39: Travel, utils, supplies, telecom, ins, repairs, bank fees, vehicle, etc.
A40: TOTAL EXPENSE ITEMS | B40: =SUM(B21:B39) | C40: =SUM(C21:C39) | D40: =SUM(D21:D39) | E40: =SUM(E21:E39)
A41: NET INCOME RECONCILIATION
A42: Net income (loss) = Income − Expenses | B42: =B18-B40 | C42: =C18-C40 | D42: =D18-D40 | E42: =E18-E40
...

Sheet 7203 - SH2 (NA)
A1: [ENTITY NAME] — Form 7203 — S Corporation Shareholder Stock and Debt Basis Limitations
A2: Tax Year Ended [MM/DD/YYYY]
A3: Shareholder: [NAME]
A4: Filed with shareholder's Form 1040. Required if SH claims loss/deduction, receives distribution, disposes of stock, or receives loan repayment.
A6: Line | B6: Description | C6: K-1 Box / Source | D6: Amount | E6: Running Basis | F6: Ties To | G6: Notes
B7: PART I — SHAREHOLDER STOCK BASIS
A8: 1 | B8: Stock basis at beginning of corporation's tax year | C8: Prior-year 7203 Ln 27 | G8: ⚠ MANUALLY ENTER — Beginning stock basis from prior-year Form 7203 Line 27 (or initial cost basis if first year). This is the MOST CRITICAL input.
A9: 2 | B9: Stock purchased or additional capital contributions during year | C9: Stock certs / PBC | D9: 0 | G9: ⚠ MANUALLY ENTER — Only if new capital contributed this year. Usually $0.
A10: 3 | B10: Basis from restored debt repayment (from Part II, if applicable) | C10: Part II below | D10: 0 | G10: Only if SH had reduced debt basis in prior year AND corp repaid some debt this year. Rare.
B11: INCREASES TO STOCK BASIS
