Workbook

Sheet 📋 Preparer Guide
A1: 1120 (C-CORP) — PREPARER'S DATA ENTRY GUIDE
A2: All manual entries, their source documents, and their destination cells — in workflow order.
A3: 🔵 BLUE = Type directly into cell (hardcoded input) 🔴 RED = From prior-year return — enter once, verify annually 🟡 YELLOW = Strategy / adjustment input 🟢 GREEN = Auto-calculated — no entry needed
A5: # | B5: WHAT TO ENTER | C5: WHERE TO FIND IT | D5: GOES INTO (TAB → CELL) | E5: ENTRY TYPE | F5: RULES / NOTES
A6: STEP 1 — PBC P&L TAB: Transcribe Client's QuickBooks Profit & Loss ↳ Pull from QuickBooks (or client-provided P&L). Every blue cell in PBC – P&L feeds the entire WTB. Get these right first.
A7: 1 | B7: Gross Receipts / Sales | C7: QB P&L → Revenue section → top line | D7: PBC – P&L B6 | E7: PBC Input | F7: Gross before returns. Ties to WTB → Pg 1 Ln 1a.
A8: 2 | B8: Returns & Allowances | C8: QB P&L → Returns & Allowances | D8: PBC – P&L B7 | E8: PBC Input | F8: Enter as negative. Ties to Pg 1 Ln 1b.
A9: 3 | B9: Cost of Goods Sold (COGS) | C9: QB P&L → COGS total | D9: PBC – P&L B12 | E9: PBC Input | F9: Ties to Pg 1 Ln 2.
A10: 4 | B10: Rental / Lease Income (Other) | C10: QB P&L → Other Income → Rental | D10: PBC – P&L B9 | E10: PBC Input | F10: AJE-01 auto-removes from OBI → Pg 1 Ln 6.
A11: 5 | B11: Interest Income | C11: QB P&L → Other Income → Interest OR 1099-INT | D11: PBC – P&L B16 | E11: PBC Input | F11: AJE-02 auto-moves → Pg 1 Ln 5.
A12: 6 | B12: Dividend Income | C12: QB P&L → Other Income → Dividends OR 1099-DIV | D12: PBC – P&L B17 | E12: PBC Input | F12: AJE-03 auto-moves → Pg 1 Ln 4 / Sch C for DRD.
A13: 7 | B13: Long-Term Capital Gains | C13: QB P&L → Other Income → Cap Gains OR 1099-B | D13: PBC – P&L B18 | E13: PBC Input | F13: AJE-04 auto-moves → Pg 1 Ln 8 / Sch D.
A14: 8 | B14: Gain on Equipment Sale | C14: QB P&L → Other Income → Gain on Disposal | D14: PBC – P&L B19 | E14: PBC Input | F14: AJE-05 auto-moves → Pg 1 Ln 9 / Form 4797.
A15: 9 | B15: Tax-Exempt / Muni Interest | C15: QB P&L → Other Income → Tax-Exempt Interest | D15: PBC – P&L B20 | E15: PBC Input | F15: AJE-17 removes from taxable income. M-1 Ln 7.
A16: 10 | B16: Unrealized Gain / Mark-to-Market | C16: QB P&L → Other Income → Unrealized Gain | D16: PBC – P&L B21 | E16: PBC Input | F16: AJE-18 removes — never taxable until realized.
A17: 11 | B17: Royalty Income | C17: QB P&L → Other Income → Royalties | D17: PBC – P&L B22 | E17: PBC Input | F17: Stays on Pg 1 Ln 7.
A18: 12 | B18: Officer Compensation | C18: QB P&L → Salaries → Officer Comp AND W-2s | D18: PBC – P&L B27 | E18: PBC Input | F18: Cross-check W-2 Box 1 total for all officers.
... A32: 26 | B32: All Other Deductions | C32: QB P&L → remaining expense lines | D32: PBC – P&L B51 | E32: PBC Input | F32: Advertising, repairs, interest, taxes, etc. Enter each line.
A33: STEP 2 — PBC BALANCE SHEET TAB: Transcribe Client's Year-End Balance Sheet ↳ All amounts are END OF YEAR (12/31/[YEAR]). Feeds Sch L EOY column and WTB balance sheet section.
A34: 27 | B34: Cash & Equivalents | C34: QB Balance Sheet → Current Assets → Cash | D34: PBC – BS B6 | E34: PBC Input | F34: Sch L Ln 1(d).
A35: 28 | B35: Accounts Receivable (gross) | C35: QB BS → AR → Gross (before allowance) | D35: PBC – BS B7 | E35: PBC Input | F35: Sch L Ln 2a.
A36: 29 | B36: Allowance for Bad Debts | C36: QB BS → AR → Allowance | D36: PBC – BS B8 | E36: PBC Input | F36: Enter as negative. Sch L Ln 2b.
A37: 30 | B37: Inventories | C37: QB BS → Current Assets → Inventory | D37: PBC – BS B9 | E37: PBC Input | F37: Sch L Ln 3.
A38: 31 | B38: Prepaid Expenses | C38: QB BS → Current Assets → Prepaid | D38: PBC – BS B10 | E38: PBC Input | F38: Sch L Ln 6.
A39: 32 | B39: Investments (Govt obligations) | C39: QB BS → Investments → US Govt | D39: PBC – BS B11 | E39: PBC Input | F39: Sch L Ln 5a.
A40: 33 | B40: Other Current Assets | C40: QB BS → Current Assets → Other | D40: PBC – BS B12 | E40: PBC Input | F40: Sch L Ln 6.
A41: 34 | B41: Land | C41: QB BS → Fixed Assets → Land | D41: PBC – BS B13 | E41: PBC Input | F41: Sch L Ln 12.
A42: 35 | B42: Buildings / Depreciable Assets | C42: QB BS → Fixed Assets → Buildings + Equipment | D42: PBC – BS B14-15 | E42: PBC Input | F42: Sch L Ln 10a — gross cost.
A43: 36 | B43: Accumulated Depreciation | C43: QB BS → Fixed Assets → Accum Depr | D43: PBC – BS B16 | E43: PBC Input | F43: Enter as negative. Sch L Ln 10b.
A44: 37 | B44: Intangible Assets | C44: QB BS → Intangibles (gross) | D44: PBC – BS B17 | E44: PBC Input | F44: Sch L Ln 13a.
A45: 38 | B45: Accumulated Amortization | C45: QB BS → Intangibles → Accum Amort | D45: PBC – BS B18 | E45: PBC Input | F45: Enter as negative. Sch L Ln 13b.
... A57: 50 | B57: Treasury Stock | C57: QB BS → Equity → Treasury Stock | D57: PBC – BS B35 | E57: PBC Input | F57: Enter as negative. Sch L Ln 27.
A58: STEP 3 — SCHEDULE L TAB: Enter Prior-Year Ending Balance Sheet (BOY Column) ↳ ⚠ All RED cells. Source: Prior-year 1120, Schedule L, Column (c)/(d) (ENDING amounts). Enter once — stays constant all year.
A59: 51 | B59: Cash — BOY | C59: PY 1120 → Sch L → Ln 1, Col (d) | D59: Sch L C6 | E59: Prior Year | F59: PY ending = CY beginning.
A60: 52 | B60: Accounts Receivable (gross) — BOY | C60: PY 1120 → Sch L → Ln 2a, Col (c) | D60: Sch L C7 | E60: Prior Year
A61: 53 | B61: Allowance for Bad Debts — BOY | C61: PY 1120 → Sch L → Ln 2b, Col (c) | D61: Sch L C8 | E61: Prior Year | F61: Enter as negative.
A62: 54 | B62: Inventories — BOY | C62: PY 1120 → Sch L → Ln 3, Col (d) | D62: Sch L C9 | E62: Prior Year
A63: 55 | B63: Tax-Exempt Securities — BOY | C63: PY 1120 → Sch L → Ln 5a, Col (d) | D63: Sch L C11 | E63: Prior Year
A64: 56 | B64: Other Current Assets — BOY | C64: PY 1120 → Sch L → Ln 6, Col (d) | D64: Sch L C12 | E64: Prior Year
A65: 57 | B65: Other Investments — BOY | C65: PY 1120 → Sch L → Ln 9, Col (d) | D65: Sch L C15 | E65: Prior Year
...

Sheet PBC - P&L
A1: PBC — PROFIT & LOSS STATEMENT
A2: [ENTITY NAME] (C-Corp) — Tax Year [YEAR]
A4: Account | B4: Amount ($)
A5: REVENUE
A6: Gross Receipts / Sales
A7: Returns & Allowances
A8: Net Sales | B8: =B6+B7
A9: Equipment Rental Income
A11: COST OF GOODS SOLD
A12: Cost of Goods Sold
A13: Gross Profit | B13: =B8-B12
A15: OTHER INCOME
A16: Interest Income (Bank)
A17: Dividend Income (Ordinary)
A18: Capital Gain — Stock Sales (LTCG)
A19: Gain on Sale of Equipment
A20: Tax-Exempt Muni Bond Interest
A21: Unrealized Gain on Investments
A22: Royalties
A23: Other Income
A24: Total Other Income | B24: =SUM(B16:B23)
A26: OFFICER COMPENSATION
A27: Officer Compensation (per W-2)
A29: SALARIES & WAGES
A30: Salaries & Wages (non-officer)
A32: DEDUCTIONS
A33: Repairs & Maintenance
A34: Bad Debts
A35: Rents
A36: Taxes & Licenses
A37: Interest Expense — Business Loans
A38: Depreciation — Vehicles (Book)
A39: Depreciation — FF&E (Book)
... A53: Other Deductions
A54: Total Deductions | B54: =SUM(B33:B53)
A56: NET INCOME (BOOK) | B56: =B13+B9+B24-B27-B30-B54

Sheet PBC - Balance Sheet
A1: PBC — BALANCE SHEET (as of 12/31/[YEAR])
A2: [ENTITY NAME] (C-Corp)
A4: Account | B4: Amount ($)
A5: ASSETS
A6: Cash & Cash Equivalents
A7: Accounts Receivable (Gross)
A8: Less: Allowance for Doubtful Accounts
A9: Inventories
A10: Prepaid Expenses
A11: Investments — Govt Obligations
A12: Other Current Assets
A13: Land
A14: Buildings/Other Depreciable Assets
A15: Depreciable Assets (Cost/Basis)
A16: Less: Accumulated Depreciation
... A19: Other Assets
A20: Total Assets | B20: =SUM(B6:B19)
A22: LIABILITIES
A23: Accounts Payable
A24: Mortgages/Notes Payable (<1 yr)
A25: Other Current Liabilities
A26: Loans from Shareholders
A27: Mortgages/Notes Payable (≥1 yr)
A28: Other Liabilities
A29: Total Liabilities | B29: =SUM(B23:B28)
A31: EQUITY
A32: Capital Stock
A33: Additional Paid-In Capital
A34: Retained Earnings (Prior Years)
A35: Retained Earnings (Current Year) | B35: =B20-B29-B32-B33-B34-B36
A36: Less: Treasury Stock
A37: Total Equity | B37: =SUM(B32:B35)-B36
A39: TOTAL LIABILITIES + EQUITY | B39: =B29+B37
A40: Balance Sheet Check (should be 0) | B40: =B20-B38

Sheet Strategy Inputs
A1: STRATEGY & ADJUSTMENT INPUTS — TYPE AMOUNTS HERE
A2: Yellow cells = INPUT. Blue font = you enter this. Black = formula/auto. M-1 items do NOT change books — just the tax return.
A5: # | B5: Adjustment Description | C5: INPUT Amount ($) | D5: Auto / Calc | E5: What This Does | F5: Flows To → AJE | G5: Flows To → WTB | H5: Type
A6: SECTION 1: PAGE 1 INCOME RECLASSIFICATIONS — Move to Correct Line or Remove
A7: 1 | B7: Equipment Rental Income (Move from OBI to Pg 1 Ln 6) | D7: ='PBC - P&L'!B9 | E7: Removes rental income from Ln 3 gross profit. Reports on Pg 1 Ln 6 (Rents). | F7: AJE-01 | G7: WTB r66 Col C | H7: Pg 1 Reclass
A8: 2 | B8: Rental Activity Expenses (Move to offset rental income) | E8: Expenses for rental activity. Netted against rental income on Pg 1 Ln 6. | F8: AJE-01 | G8: WTB r121 Col C | H8: Pg 1 Reclass
A9: 3 | B9: Interest Income (Move to Pg 1 Ln 5) | D9: ='PBC - P&L'!B16 | E9: Move from OBI to Pg 1 Ln 5 (Interest). | F9: AJE-02 | G9: WTB r68 Col C | H9: Pg 1 Reclass
A10: 4 | B10: Dividend Income (Move to Pg 1 Ln 4 via Sch C) | D10: ='PBC - P&L'!B17 | E10: Move from OBI to Pg 1 Ln 4 (Dividends). Subject to DRD on Sch C. | F10: AJE-03 | G10: WTB r69 Col C | H10: Pg 1 Reclass
A11: 5 | B11: Capital Gain — Stock Sales (Move to Pg 1 Ln 8 via Sch D) | D11: ='PBC - P&L'!B18 | E11: Move from OBI to Pg 1 Ln 8 (Capital Gain). Net capital loss limited to $0. | F11: AJE-04 | G11: WTB r70 Col C | H11: Pg 1 Reclass
A12: 6 | B12: Gain on Sale of Equipment (Move to Pg 1 Ln 9 via Form 4797) | D12: ='PBC - P&L'!B19 | E12: Move from OBI to Pg 1 Ln 9. §1245 recapture = ordinary. §1231 = Ln 9. | F12: AJE-05 | G12: WTB r71 Col C | H12: Pg 1 Reclass
A13: 7 | B13: Tax-Exempt Muni Bond Interest (Remove entirely — not taxable) | D13: ='PBC - P&L'!B20 | E13: Remove from income. Not taxable. Hits M-1 Ln 7. Reduces DRD computation. | F13: AJE-17 | G13: WTB r72 Col C + Col F | H13: M-1 + Remove
A14: 8 | B14: Unrealized Gain on Investments (Book only — remove for tax) | D14: ='PBC - P&L'!B21 | E14: Book has unrealized gain; tax does not. Remove. M-1 Ln 8. | F14: AJE-18 | G14: WTB r73 Col C + Col F | H14: M-1 Adj
A15: SECTION 2: M-1 NONDEDUCTIBLE EXPENSES — On Books but Not Deductible on Return
A16: 9 | B16: Business Meals — 50% Nondeductible (Tax only deducts 50%) | D16: ='PBC - P&L'!B45*0.5 | E16: Auto-calculates 50%. M-1 Ln 5c addback. | F16: AJE-07 | G16: WTB r99 Col F only | H16: M-1 Only
A17: 10 | B17: Entertainment — 100% Nondeductible | D17: ='PBC - P&L'!B46 | E17: 100% nondeductible. M-1 Ln 5d addback. | F17: AJE-08 | G17: WTB r100 Col C + F | H17: M-1 + Col C
A18: 11 | B18: Charitable — Excess Over 10% Limit (Deductible up to 10% of taxable income) | E18: C-corps deduct charity on Pg 1 Ln 19 (up to 10% limit). Enter EXCESS here. | F18: AJE-09 | G18: WTB r114 Col F | H18: M-1 (excess)
A19: 12 | B19: Political Contributions — 100% Nondeductible | D19: ='PBC - P&L'!B48 | E19: Always nondeductible. M-1 addback. | F19: AJE-10 | G19: WTB r115 Col F only | H19: M-1 Only
A20: 13 | B20: Penalties & Fines — 100% Nondeductible | D20: ='PBC - P&L'!B49 | E20: Nondeductible §162(f). M-1 addback. | F20: AJE-11 | G20: WTB r116 Col F only | H20: M-1 Only
A21: 14 | B21: Life Insurance (Corp Beneficiary) — Nondeductible | D21: ='PBC - P&L'!B50 | E21: Nondeductible when corp is beneficiary. M-1 addback. | F21: AJE-12 | G21: WTB r117 Col F only | H21: M-1 Only
A22: 15 | B22: Club Dues — Nondeductible | D22: ='PBC - P&L'!B51 | E22: Always nondeductible. M-1 addback. | F22: AJE-13 | G22: WTB r118 Col F only | H22: M-1 Only
A23: SECTION 3: DEPRECIATION — Remove Book, Add Tax (MACRS / §179)
A24: 16 | B24: Total Book Depreciation (Auto-pulls — ALL book depr removed) | D24: ='PBC - P&L'!B38+'PBC - P&L'!B39+'PBC - P&L'!B40+'PBC - P&L'!B41 | E24: Entire book depr removed from Pg 1. Replaced by tax depr. M-1 Ln 5a. | F24: AJE-14 | G24: WTB r105-108 Col C + F | H24: Book→Tax
A25: 17 | B25: Tax Depreciation — MACRS/Bonus (ENTER FROM TAX SOFTWARE) | E25: Enter total from Form 4562. Goes to Pg 1 Ln 20. M-1 Ln 8a. | F25: AJE-15 | G25: WTB r109 Col D + F | H25: Tax Only
A26: 18 | B26: §179 Deduction (ENTER FROM TAX SOFTWARE) | E26: Enter from 4562 Part I. Goes to Pg 1 Ln 20. M-1 Ln 8b. | F26: AJE-16 | G26: WTB r110 Col D + F | H26: Tax Only
A27: SECTION 4: TAX STRATEGY ADJUSTMENTS — C-Corp Specific
A28: 19 | B28: NOL Carryforward (Pg 1 Ln 29a — limited to 80% of taxable income) | E28: Enter NOL available. Limited to 80% of taxable income (pre-NOL). Pg 1 Ln 29a. | F28: N/A (Pg 1) | G28: WTB Ln 29a | H28: Pg 1 Deduction
A29: 20 | B29: Dividends Received Deduction (DRD) (Pg 1 Ln 29b from Sch C) | E29: 50%/65%/100% DRD depending on ownership %. From Schedule C. | F29: N/A (Pg 1) | G29: WTB Ln 29b | H29: Pg 1 Deduction
A30: 21 | B30: Officer Salary Adjustment (CHANGE only — + or −) | E30: Enter CHANGE from PBC amount. $0 if correct. Pg 1 Ln 12. | F30: New AJE | G30: WTB r85 Officer comp | H30: Entity Adj
A31: 22 | B31: Retirement Plan — Additional Contribution (Amount NOT on PBC) | E31: Additional employer contribution not on PBC. Pg 1 Ln 23. | F31: New AJE | G31: WTB Pg 1 Ln 23 | H31: Entity Deduction

Sheet Adjusting Entries
A1: ADJUSTING ENTRIES — Book-to-Tax Adjustments
A2: Auto-generated from PBC + Strategy Inputs. Blue = manual override available.
A4: AJE # | B4: Description | C4: Debit | D4: Credit | E4: Net Effect on Taxable Income | F4: Source
A5: AJE-01 | B5: Rental Income Reclass (OBI → Pg 1 Ln 6) | C5: ='Strategy Inputs'!D7 | E5: Remove from gross profit, report on Pg 1 Ln 6 | F5: Strategy Inputs / PBC
A6: AJE-02 | B6: Interest Income Reclass (OBI → Pg 1 Ln 5) | C6: ='Strategy Inputs'!D9 | E6: Remove from OBI, Pg 1 Ln 5 | F6: Strategy Inputs / PBC
A7: AJE-03 | B7: Dividend Income Reclass (OBI → Pg 1 Ln 4 / Sch C) | C7: ='Strategy Inputs'!D10 | E7: Remove from OBI, Pg 1 Ln 4 via Sch C | F7: Strategy Inputs / PBC
A8: AJE-04 | B8: Capital Gain Reclass (OBI → Pg 1 Ln 8) | C8: ='Strategy Inputs'!D11 | E8: Remove from OBI, Pg 1 Ln 8 via Sch D | F8: Strategy Inputs / PBC
A9: AJE-05 | B9: Equipment Sale Reclass (OBI → Pg 1 Ln 9) | C9: ='Strategy Inputs'!D12 | E9: Remove from OBI, Pg 1 Ln 9 via 4797 | F9: Strategy Inputs / PBC
A10: AJE-07 | B10: Meals 50% Disallowance (M-1 addback only) | D10: ='Strategy Inputs'!D15 | E10: No Col C adj. M-1 Ln 5c addback | F10: Strategy Inputs / PBC
A11: AJE-08 | B11: Entertainment 100% Disallowance | C11: ='Strategy Inputs'!D16 | E11: Remove from deductions. M-1 Ln 5d | F11: Strategy Inputs / PBC
A12: AJE-09 | B12: Charitable Excess (>10% limit) (M-1 addback for excess) | D12: ='Strategy Inputs'!C17 | E12: Excess over 10% limit. Carryforward 5 yrs | F12: Strategy Inputs / PBC
A13: AJE-10 | B13: Political Contributions Disallowance | D13: ='Strategy Inputs'!D18 | E13: M-1 addback | F13: Strategy Inputs / PBC
A14: AJE-11 | B14: Penalties & Fines Disallowance | D14: ='Strategy Inputs'!D19 | E14: M-1 addback | F14: Strategy Inputs / PBC
A15: AJE-12 | B15: Life Insurance Disallowance | D15: ='Strategy Inputs'!D20 | E15: M-1 addback | F15: Strategy Inputs / PBC
A16: AJE-13 | B16: Club Dues Disallowance | D16: ='Strategy Inputs'!D21 | E16: M-1 addback | F16: Strategy Inputs / PBC
A17: AJE-14 | B17: Remove Book Depreciation (All categories) | C17: ='Strategy Inputs'!D22 | E17: Remove book depr. Replace with tax | F17: Strategy Inputs / PBC
A18: AJE-15 | B18: Add Tax Depreciation (MACRS/Bonus) | D18: ='Strategy Inputs'!C23 | E18: Tax depr replaces book. Pg 1 Ln 20 | F18: Strategy Inputs / PBC
A19: AJE-16 | B19: Add §179 Deduction | D19: ='Strategy Inputs'!C24 | E19: §179 added. Pg 1 Ln 20 | F19: Strategy Inputs / PBC
A20: AJE-17 | B20: Remove Tax-Exempt Interest (Muni bonds — not taxable) | C20: ='Strategy Inputs'!D13 | E20: Remove from income. M-1 Ln 7 | F20: Strategy Inputs / PBC
A21: AJE-18 | B21: Remove Unrealized Gain (Book only — not realized for tax) | C21: ='Strategy Inputs'!D14 | E21: Remove from income. M-1 Ln 8 | F21: Strategy Inputs / PBC
A23: PROOF | B23: Total Debits − Total Credits (should be 0)

Sheet Schedule M-1
A1: SCHEDULE M-1 — Reconciliation of Income (Loss) per Books With Income per Return
A2: Form 1120 — [ENTITY NAME]
A4: Line | B4: Description | C4: Amount | D4: Source / Notes
A5: 1 | B5: Net income (loss) per books | C5: ='PBC - P&L'!B56 | D5: PBC Net Income (Book)
A6: 2 | B6: Federal income tax per books | D6: Accrued federal tax (enter from books)
A7: 3 | B7: Excess of capital losses over capital gains | D7: C-corps: net cap loss not deductible
A8: 4 | B8: Income subject to tax not recorded on books | D8: (Rare)
A9: 5a | B9: Expenses on books not deducted — Tax-exempt interest expenses | D9: Expenses allocable to tax-exempt income
A10: 5b | B10: Expenses on books not deducted — Depreciation | C10: ='Strategy Inputs'!D24 | D10: Book depr removed (replaced by tax)
A11: 5c | B11: Expenses on books not deducted — Meals (50%) | C11: ='Strategy Inputs'!D16 | D11: 50% meals disallowance
A12: 5d | B12: Expenses on books not deducted — Entertainment | C12: ='Strategy Inputs'!D17 | D12: 100% nondeductible
A13: 5e | B13: Expenses on books not deducted — Political | C13: ='Strategy Inputs'!C18 | D13: 100% nondeductible
A14: 5f | B14: Expenses on books not deducted — Penalties | C14: ='Strategy Inputs'!D19 | D14: 100% nondeductible
A15: 5g | B15: Expenses on books not deducted — Life insurance | C15: ='Strategy Inputs'!D20 | D15: Corp beneficiary = nondeductible
A16: 5h | B16: Expenses on books not deducted — Club dues | C16: ='Strategy Inputs'!D21 | D16: Always nondeductible
A17: 5i | B17: Expenses on books not deducted — Charitable excess | C17: ='Strategy Inputs'!D22 | D17: Amount exceeding 10% limit
A18: 6 | B18: Total of lines 1 through 5 | C18: =C5+C6+C7+C8+C9+C10+C11+C12+C13+C14+C15+C16+C17 | D18: Sum
A19: 7 | B19: Income on return not in books — Tax-exempt interest | C19: =-'Strategy Inputs'!D13 | D19: Remove muni bond interest
A20: 8a | B20: Deductions on return not in books — Tax depreciation | C20: ='Strategy Inputs'!C23 | D20: MACRS/Bonus from 4562
A21: 8b | B21: Deductions on return not in books — §179 | C21: ='Strategy Inputs'!C24 | D21: §179 election
A22: 8c | B22: Deductions on return not in books — Unrealized gain reversal | C22: =-'Strategy Inputs'!D14 | D22: Not realized for tax
A23: 9 | B23: Total of lines 7 and 8 | C23: =C19+C20+C21+C22 | D23: Sum
A24: 10 | B24: Income (Ln 28, Pg 1) — Line 6 minus Line 9 | C24: =C18-C23 | D24: Should tie to Pg 1 Ln 28

Sheet Schedule L
A1: SCHEDULE L — Balance Sheets per Books
A2: Form 1120 — [ENTITY NAME] — Tax Year [YEAR]
A4: Ln | B4: Description | C4: (a)/(b) BOY | D4: (c)/(d) EOY | E4: Variance
A5: ASSETS
A6: 1 | B6: Cash | D6: ='PBC - Balance Sheet'!B6 | E6: =D6-C6
A7: 2a | B7: Trade notes & accounts receivable (gross) | D7: ='PBC - Balance Sheet'!B7 | E7: =D7-C7
A8: 2b | B8: Less: Allowance for bad debts | D8: ='PBC - Balance Sheet'!B8 | E8: =D8-C8
A9: 3 | B9: Inventories | D9: ='PBC - Balance Sheet'!B9 | E9: =D9-C9
A10: 4 | B10: U.S. government obligations
A11: 5a | B11: Tax-exempt securities | D11: ='PBC - Balance Sheet'!B11 | E11: =D11-C11
A12: 6 | B12: Other current assets | D12: ='PBC - Balance Sheet'!B10++'PBC - Balance Sheet'!B12 | E12: =D12-C12
A13: 7 | B13: Loans to shareholders
A14: 8 | B14: Mortgage and real estate loans
A15: 9 | B15: Other investments | D15: ='PBC - Balance Sheet'!B19 | E15: =D15-C15
A16: 10a | B16: Buildings and other depreciable assets (a) | D16: ='PBC - Balance Sheet'!B14+'PBC - Balance Sheet'!B15 | E16: =D16-C16
A17: 10b | B17: Less: Accumulated depreciation (b) | D17: ='PBC - Balance Sheet'!B16 | E17: =D17-C17
A18: 11a | B18: Depletable assets
A19: 11b | B19: Less: Accumulated depletion
A20: 12 | B20: Land (net of any amortization) | D20: ='PBC - Balance Sheet'!B13 | E20: =D20-C20
A21: 13a | B21: Intangible assets (a) | D21: ='PBC - Balance Sheet'!B17 | E21: =D21-C21
A22: 13b | B22: Less: Accumulated amortization (b) | D22: ='PBC - Balance Sheet'!B18 | E22: =D22-C22
A23: 14 | B23: Other assets | D23: ='PBC - Balance Sheet'!B19 | E23: =D23-C23
A24: 15 | B24: Total assets | C24: =SUM(C6:C23) | D24: =SUM(D6:D23)
A25: LIABILITIES AND SHAREHOLDERS' EQUITY
A26: 16 | B26: Accounts payable | D26: ='PBC - Balance Sheet'!B23 | E26: =D26-C26
A27: 17 | B27: Mortgages, notes, bonds payable (<1 yr) | D27: ='PBC - Balance Sheet'!B24 | E27: =D27-C27
A28: 18 | B28: Other current liabilities | D28: ='PBC - Balance Sheet'!B25 | E28: =D28-C28
A29: 19 | B29: Loans from shareholders | D29: ='PBC - Balance Sheet'!B26 | E29: =D29-C29
A30: 20 | B30: Mortgages, notes, bonds payable (≥1 yr) | D30: ='PBC - Balance Sheet'!B27 | E30: =D30-C30
A31: 21 | B31: Other liabilities | D31: ='PBC - Balance Sheet'!B28 | E31: =D31-C31
A32: 22 | B32: Capital stock (a) preferred / (b) common | D32: ='PBC - Balance Sheet'!B31 | E32: =D32-C32
A33: 23 | B33: Additional paid-in capital | D33: ='PBC - Balance Sheet'!B32 | E33: =D33-C33
A34: 24 | B34: Retained earnings — Appropriated
A35: 25 | B35: Retained earnings — Unappropriated | D35: ='PBC - Balance Sheet'!B33+'PBC - Balance Sheet'!B34 | E35: =D35-C35
A36: 26 | B36: Adjustments to shareholders' equity
A37: 27 | B37: Less: Cost of treasury stock | D37: ='PBC - Balance Sheet'!B35 | E37: =D37-C37
A38: 28 | B38: Total liabilities and shareholders' equity | C38: =SUM(C26:C37) | D38: =SUM(D26:D37)
B40: Sch L Check: Assets − Liabilities+Equity (should be 0) | C40: =C24-C38 | D40: =D24-D38

Sheet Schedule M-2
A1: SCHEDULE M-2 — Analysis of Unappropriated Retained Earnings per Books (Ln 25, Sch L)
A2: Form 1120 — [ENTITY NAME] — Tax Year [YEAR]
A4: Line | B4: Description | C4: Amount
A5: 1 | B5: Balance at beginning of year
A6: 2 | B6: Net income (loss) per books | C6: ='PBC - P&L'!B56
A7: 3 | B7: Other increases (itemize)
A8: 4 | B8: Total of lines 1, 2, and 3 | C8: =C5+C6+C7
A9: 5a | B9: Distributions — Cash
A10: 5b | B10: Distributions — Stock
A11: 5c | B11: Distributions — Property
A12: 6 | B12: Other decreases (itemize)
A13: 7 | B13: Total of lines 5 and 6 | C13: =C9+C10+C11+C12
A14: 8 | B14: Balance at end of year (Ln 4 − Ln 7) | C14: =C8-C13
A16: M-2 NOTES: | B16: Line 8 must equal Sch L Line 25(d). If not, check: (1) beginning balance from PY, (2) net income ties to Pg 1 books, (3) all distributions recorded.

Sheet Schedule J
A1: SCHEDULE J — TAX COMPUTATION AND PAYMENT
A2: Form 1120 — C-Corps pay tax at 21% flat rate
A4: Line | B4: Description | C4: Amount | D4: Notes
A5: 2 | B5: Income tax (21% × Pg 1 Ln 30 taxable income) | C5: ='Working Trial Balance'!D87*0.21 | D5: Flat 21% rate. Enter Pg 1 Ln 30 × 0.21
A6: 3 | B6: Alternative minimum tax (if applicable) | D6: AMT repealed for corps post-TCJA but CAMT may apply if >$1B avg revenue
A7: 4 | B7: Total — add lines 2 and 3 | C7: =C5+C6
A8: 5a | B8: Foreign tax credit (Form 1118)
A9: 5b | B9: General business credit (Form 3800)
A10: 5c | B10: Credit for prior year minimum tax (Form 8827)
A11: 5d | B11: Other credits
A12: 6 | B12: Total credits | C12: =SUM(C8:C11)
A13: 7 | B13: Subtract Line 6 from Line 4 | C13: =C7-C12
A14: 8 | B14: Personal holding company tax (Sch PH) | D14: Only if PHC
A15: 9a | B15: Recapture of investment credit
A16: 9b | B16: Recapture of low-income housing credit
A17: 9c | B17: Interest due under look-back method
A18: 9d | B18: Other taxes
A19: 10 | B19: Total tax — add lines 7 through 9d | C19: =C13+C14+C15+C16+C17+C18
A21: PAYMENTS AND CREDITS
A22: 11 | B22: Estimated tax payments + overpayment from PY
A23: 12 | B23: Total tax (to Form 1120 Ln 31) | C23: =C19 | D23: Ties to Pg 1 Ln 31

Sheet Schedule M-3
A1: SCHEDULE M-3 — Net Income (Loss) Reconciliation for Corps With Total Assets ≥ $10M
A3: This tab is a PLACEHOLDER. Only required if total assets ≥ $10M or voluntary election.
A4: If needed, build out Part I (Financial Info), Part II (Income Items), Part III (Expense Items) with columns for Book, Temp Diff, Perm Diff, Tax.

Sheet Working Trial Balance
A1: WORKING TRIAL BALANCE — FORM 1120 (C-CORP)
A2: [ENTITY NAME] — EIN: XX-XXXXXXX — Tax Year Ended December 31, [YEAR]
A3: Col A = Book (PBC) | Col B = Book-to-Tax Adj | Col C = A + B = Tax Return Amount | Col D = M-1 Adjustments | Col E = Ties to (Return Line)
A5: Account / Description | B5: A: Book (PBC) | C5: B: Sch Adj (Book→Tax) | D5: C: Tax Return Amount (A+B) | E5: D: M-1 Adjustments | F5: E: Ties to (Return Line)
A6: BALANCE SHEET (Assets)
A7: Cash & Cash Equivalents | B7: ='PBC - Balance Sheet'!B6 | D7: =B7+C7 | F7: Sch L Ln 1
A8: Accounts Receivable (Gross) | B8: ='PBC - Balance Sheet'!B7 | D8: =B8+C8 | F8: Sch L Ln 2a
A9: Less: Allowance for Bad Debts | B9: ='PBC - Balance Sheet'!B8 | D9: =B9+C9 | F9: Sch L Ln 2b
A10: Inventories | B10: ='PBC - Balance Sheet'!B9 | D10: =B10+C10 | F10: Sch L Ln 3
A11: Prepaid Expenses | B11: ='PBC - Balance Sheet'!B10 | D11: =B11+C11 | F11: Sch L Ln 6
A12: Investments — Govt Obligations | B12: ='PBC - Balance Sheet'!B11 | D12: =B12+C12 | F12: Sch L Ln 5a
A13: Other Current Assets | B13: ='PBC - Balance Sheet'!B12 | D13: =B13+C13 | F13: Sch L Ln 6
A14: Land | B14: ='PBC - Balance Sheet'!B13 | D14: =B14+C14 | F14: Sch L Ln 12
A15: Buildings/Depreciable Assets | B15: ='PBC - Balance Sheet'!B14+'PBC - Balance Sheet'!B15 | D15: =B15+C15 | F15: Sch L Ln 10a
A16: Less: Accum Depreciation | B16: ='PBC - Balance Sheet'!B16 | D16: =B16+C16 | F16: Sch L Ln 10b
A17: Intangible Assets | B17: ='PBC - Balance Sheet'!B17 | D17: =B17+C17 | F17: Sch L Ln 13a
A18: Less: Accum Amortization | B18: ='PBC - Balance Sheet'!B18 | D18: =B18+C18 | F18: Sch L Ln 13b
A19: Other Assets | B19: ='PBC - Balance Sheet'!B19 | D19: =B19+C19 | F19: Sch L Ln 14
A20: TOTAL ASSETS | B20: =SUM(B7:B19) | D20: =SUM(D7:D19) | F20: Sch L Ln 15
A21: BALANCE SHEET (Liabilities)
A22: Accounts Payable | B22: ='PBC - Balance Sheet'!B23 | D22: =B22+C22 | F22: Sch L Ln 16
A23: Mortgages/Notes (<1 yr) | B23: ='PBC - Balance Sheet'!B24 | D23: =B23+C23 | F23: Sch L Ln 17
A24: Other Current Liabilities | B24: ='PBC - Balance Sheet'!B25 | D24: =B24+C24 | F24: Sch L Ln 18
A25: Loans from Shareholders | B25: ='PBC - Balance Sheet'!B26 | D25: =B25+C25 | F25: Sch L Ln 19
A26: Mortgages/Notes (≥1 yr) | B26: ='PBC - Balance Sheet'!B27 | D26: =B26+C26 | F26: Sch L Ln 20
A27: Other Liabilities | B27: ='PBC - Balance Sheet'!B28 | D27: =B27+C27 | F27: Sch L Ln 21
A28: TOTAL LIABILITIES | B28: =SUM(B22:B27) | D28: =SUM(D22:D27)
A29: BALANCE SHEET (Equity)
A30: Capital Stock | B30: ='PBC - Balance Sheet'!B32 | D30: =B30+C30 | F30: Sch L Ln 22
A31: Additional Paid-In Capital | B31: ='PBC - Balance Sheet'!B33 | D31: =B31+C31 | F31: Sch L Ln 23
A32: Retained Earnings (Prior Years) | B32: ='PBC - Balance Sheet'!B34 | D32: =B32+C32 | F32: Sch L Ln 25 (part)
A33: Retained Earnings (Current Year) | B33: ='PBC - Balance Sheet'!B35 | D33: =B33+C33 | F33: Sch L Ln 25 (part)
A34: Less: Treasury Stock | B34: ='PBC - Balance Sheet'!B36 | D34: =B34+C34 | F34: Sch L Ln 27
A35: TOTAL EQUITY | B35: =SUM(B30:B34) | D35: =SUM(D30:D34)
A36: BS CHECK (should be 0) | B36: =B20-B28-B35 | D36: =D20-D28-D35
A38: INCOME (Page 1)
A39: Gross Receipts / Sales | B39: ='PBC - P&L'!B6 | D39: =B39+C39 | F39: Pg 1 Ln 1a
A40: Returns & Allowances | B40: ='PBC - P&L'!B7 | D40: =B40+C40 | F40: Pg 1 Ln 1b
A41: Net Sales | B41: ='PBC - P&L'!B8 | D41: =B41+C41 | F41: Pg 1 Ln 1c
A42: COGS | B42: ='PBC - P&L'!B12 | D42: =B42+C42 | F42: Pg 1 Ln 2
...
